WARNING:django.request:Not Found: /obtain_sensors_from_session/function(e,t){return new S.fn.init(e,t)}
WARNING:django.request:Not Found: /obtain_sensors_from_session/function(e,t){return new S.fn.init(e,t)}
WARNING:django.request:Not Found: /obtain_sensors_from_session/function(e,t){return new S.fn.init(e,t)}
WARNING:django.request:Not Found: /obtain_sensors_from_session/function(e,t){return new S.fn.init(e,t)}
WARNING:django.request:Not Found: /obtain_sensors_from_session/function(e,t){return new S.fn.init(e,t)}
INFO:django.utils.autoreload:/home/martin/PycharmProjects/Torque/models/views.py changed, reloading.
INFO:django.utils.autoreload:/home/martin/PycharmProjects/Torque/models/views.py changed, reloading.
INFO:django.utils.autoreload:/home/martin/PycharmProjects/Torque/models/views.py changed, reloading.
INFO:django.utils.autoreload:/home/martin/PycharmProjects/Torque/models/views.py changed, reloading.
INFO:django.utils.autoreload:/home/martin/PycharmProjects/Torque/models/views.py changed, reloading.
INFO:django.utils.autoreload:/home/martin/PycharmProjects/Torque/models/views.py changed, reloading.
ERROR:django.request:Internal Server Error: /sensor_from_session/81/
Traceback (most recent call last):
  File "/home/martin/PycharmProjects/Torque/venv/lib/python3.8/site-packages/django/core/handlers/exception.py", line 47, in inner
    response = get_response(request)
  File "/home/martin/PycharmProjects/Torque/venv/lib/python3.8/site-packages/django/core/handlers/base.py", line 181, in _get_response
    response = wrapped_callback(request, *callback_args, **callback_kwargs)
  File "/home/martin/PycharmProjects/Torque/models/views.py", line 464, in obtain_sensors_from_session
    return JsonResponse(data=sensors)
  File "/home/martin/PycharmProjects/Torque/venv/lib/python3.8/site-packages/django/http/response.py", line 560, in __init__
    raise TypeError(
TypeError: In order to allow non-dict objects to be serialized set the safe parameter to False.
ERROR:django.request:Internal Server Error: /sensor_from_session/311/
Traceback (most recent call last):
  File "/home/martin/PycharmProjects/Torque/venv/lib/python3.8/site-packages/django/core/handlers/exception.py", line 47, in inner
    response = get_response(request)
  File "/home/martin/PycharmProjects/Torque/venv/lib/python3.8/site-packages/django/core/handlers/base.py", line 181, in _get_response
    response = wrapped_callback(request, *callback_args, **callback_kwargs)
  File "/home/martin/PycharmProjects/Torque/models/views.py", line 464, in obtain_sensors_from_session
    return JsonResponse(data=sensors)
  File "/home/martin/PycharmProjects/Torque/venv/lib/python3.8/site-packages/django/http/response.py", line 560, in __init__
    raise TypeError(
TypeError: In order to allow non-dict objects to be serialized set the safe parameter to False.
INFO:django.utils.autoreload:/home/martin/PycharmProjects/Torque/models/views.py changed, reloading.
ERROR:django.request:Internal Server Error: /sensor_from_session/213/
Traceback (most recent call last):
  File "/home/martin/PycharmProjects/Torque/venv/lib/python3.8/site-packages/django/core/handlers/exception.py", line 47, in inner
    response = get_response(request)
  File "/home/martin/PycharmProjects/Torque/venv/lib/python3.8/site-packages/django/core/handlers/base.py", line 181, in _get_response
    response = wrapped_callback(request, *callback_args, **callback_kwargs)
  File "/home/martin/PycharmProjects/Torque/models/views.py", line 464, in obtain_sensors_from_session
    return JsonResponse(data=sensors, safe=False)
  File "/home/martin/PycharmProjects/Torque/venv/lib/python3.8/site-packages/django/http/response.py", line 567, in __init__
    data = json.dumps(data, cls=encoder, **json_dumps_params)
  File "/usr/lib/python3.8/json/__init__.py", line 234, in dumps
    return cls(
  File "/usr/lib/python3.8/json/encoder.py", line 199, in encode
    chunks = self.iterencode(o, _one_shot=True)
  File "/usr/lib/python3.8/json/encoder.py", line 257, in iterencode
    return _iterencode(o, 0)
  File "/home/martin/PycharmProjects/Torque/venv/lib/python3.8/site-packages/django/core/serializers/json.py", line 105, in default
    return super().default(o)
  File "/usr/lib/python3.8/json/encoder.py", line 179, in default
    raise TypeError(f'Object of type {o.__class__.__name__} '
TypeError: Object of type QuerySet is not JSON serializable
ERROR:django.request:Internal Server Error: /sensor_from_session/70/
Traceback (most recent call last):
  File "/home/martin/PycharmProjects/Torque/venv/lib/python3.8/site-packages/django/core/handlers/exception.py", line 47, in inner
    response = get_response(request)
  File "/home/martin/PycharmProjects/Torque/venv/lib/python3.8/site-packages/django/core/handlers/base.py", line 181, in _get_response
    response = wrapped_callback(request, *callback_args, **callback_kwargs)
  File "/home/martin/PycharmProjects/Torque/models/views.py", line 464, in obtain_sensors_from_session
    return JsonResponse(data=sensors, safe=False)
  File "/home/martin/PycharmProjects/Torque/venv/lib/python3.8/site-packages/django/http/response.py", line 567, in __init__
    data = json.dumps(data, cls=encoder, **json_dumps_params)
  File "/usr/lib/python3.8/json/__init__.py", line 234, in dumps
    return cls(
  File "/usr/lib/python3.8/json/encoder.py", line 199, in encode
    chunks = self.iterencode(o, _one_shot=True)
  File "/usr/lib/python3.8/json/encoder.py", line 257, in iterencode
    return _iterencode(o, 0)
  File "/home/martin/PycharmProjects/Torque/venv/lib/python3.8/site-packages/django/core/serializers/json.py", line 105, in default
    return super().default(o)
  File "/usr/lib/python3.8/json/encoder.py", line 179, in default
    raise TypeError(f'Object of type {o.__class__.__name__} '
TypeError: Object of type QuerySet is not JSON serializable
INFO:django.utils.autoreload:/home/martin/PycharmProjects/Torque/models/views.py changed, reloading.
ERROR:django.request:Internal Server Error: /sensor_from_session/81/
Traceback (most recent call last):
  File "/home/martin/PycharmProjects/Torque/venv/lib/python3.8/site-packages/django/core/handlers/exception.py", line 47, in inner
    response = get_response(request)
  File "/home/martin/PycharmProjects/Torque/venv/lib/python3.8/site-packages/django/core/handlers/base.py", line 181, in _get_response
    response = wrapped_callback(request, *callback_args, **callback_kwargs)
  File "/home/martin/PycharmProjects/Torque/models/views.py", line 464, in obtain_sensors_from_session
    return HttpResponse(json.simplejson.dumps(sensors), mimetype="application/json")
AttributeError: module 'json' has no attribute 'simplejson'
INFO:django.utils.autoreload:/home/martin/PycharmProjects/Torque/models/views.py changed, reloading.
ERROR:django.request:Internal Server Error: /sensor_from_session/81/
Traceback (most recent call last):
  File "/home/martin/PycharmProjects/Torque/venv/lib/python3.8/site-packages/django/core/handlers/exception.py", line 47, in inner
    response = get_response(request)
  File "/home/martin/PycharmProjects/Torque/venv/lib/python3.8/site-packages/django/core/handlers/base.py", line 181, in _get_response
    response = wrapped_callback(request, *callback_args, **callback_kwargs)
  File "/home/martin/PycharmProjects/Torque/models/views.py", line 464, in obtain_sensors_from_session
    return HttpResponse(json.dumps(sensors), mimetype="application/json")
  File "/usr/lib/python3.8/json/__init__.py", line 231, in dumps
    return _default_encoder.encode(obj)
  File "/usr/lib/python3.8/json/encoder.py", line 199, in encode
    chunks = self.iterencode(o, _one_shot=True)
  File "/usr/lib/python3.8/json/encoder.py", line 257, in iterencode
    return _iterencode(o, 0)
  File "/usr/lib/python3.8/json/encoder.py", line 179, in default
    raise TypeError(f'Object of type {o.__class__.__name__} '
TypeError: Object of type QuerySet is not JSON serializable
INFO:django.utils.autoreload:/home/martin/PycharmProjects/Torque/models/views.py changed, reloading.
INFO:django.utils.autoreload:/home/martin/PycharmProjects/Torque/models/views.py changed, reloading.
ERROR:django.request:Internal Server Error: /sensor_from_session/280/
Traceback (most recent call last):
  File "/home/martin/PycharmProjects/Torque/venv/lib/python3.8/site-packages/django/core/handlers/exception.py", line 47, in inner
    response = get_response(request)
  File "/home/martin/PycharmProjects/Torque/venv/lib/python3.8/site-packages/django/core/handlers/base.py", line 181, in _get_response
    response = wrapped_callback(request, *callback_args, **callback_kwargs)
  File "/home/martin/PycharmProjects/Torque/models/views.py", line 465, in obtain_sensors_from_session
    return Response(json.dumps(sensors), mimetype="application/json")
  File "/usr/lib/python3.8/json/__init__.py", line 231, in dumps
    return _default_encoder.encode(obj)
  File "/usr/lib/python3.8/json/encoder.py", line 199, in encode
    chunks = self.iterencode(o, _one_shot=True)
  File "/usr/lib/python3.8/json/encoder.py", line 257, in iterencode
    return _iterencode(o, 0)
  File "/usr/lib/python3.8/json/encoder.py", line 179, in default
    raise TypeError(f'Object of type {o.__class__.__name__} '
TypeError: Object of type QuerySet is not JSON serializable
INFO:django.utils.autoreload:/home/martin/PycharmProjects/Torque/models/views.py changed, reloading.
INFO:django.utils.autoreload:/home/martin/PycharmProjects/Torque/models/views.py changed, reloading.
INFO:django.utils.autoreload:/home/martin/PycharmProjects/Torque/models/views.py changed, reloading.
ERROR:django.request:Internal Server Error: /sensor_from_session/10/
Traceback (most recent call last):
  File "/home/martin/PycharmProjects/Torque/venv/lib/python3.8/site-packages/django/core/handlers/exception.py", line 47, in inner
    response = get_response(request)
  File "/home/martin/PycharmProjects/Torque/venv/lib/python3.8/site-packages/django/core/handlers/base.py", line 181, in _get_response
    response = wrapped_callback(request, *callback_args, **callback_kwargs)
  File "/home/martin/PycharmProjects/Torque/models/views.py", line 459, in obtain_sensors_from_session
    sensors = sensors.values_list(['sensor_id', 'sensor__user_full_name'], flat=True)
  File "/home/martin/PycharmProjects/Torque/venv/lib/python3.8/site-packages/django/db/models/query.py", line 851, in values_list
    field_names = {f for f in fields if not hasattr(f, 'resolve_expression')}
  File "/home/martin/PycharmProjects/Torque/venv/lib/python3.8/site-packages/django/db/models/query.py", line 851, in <setcomp>
    field_names = {f for f in fields if not hasattr(f, 'resolve_expression')}
TypeError: unhashable type: 'list'
INFO:django.utils.autoreload:/home/martin/PycharmProjects/Torque/models/views.py changed, reloading.
ERROR:django.request:Internal Server Error: /sensor_from_session/300/
Traceback (most recent call last):
  File "/home/martin/PycharmProjects/Torque/venv/lib/python3.8/site-packages/django/core/handlers/exception.py", line 47, in inner
    response = get_response(request)
  File "/home/martin/PycharmProjects/Torque/venv/lib/python3.8/site-packages/django/core/handlers/base.py", line 181, in _get_response
    response = wrapped_callback(request, *callback_args, **callback_kwargs)
  File "/home/martin/PycharmProjects/Torque/models/views.py", line 459, in obtain_sensors_from_session
    sensors = sensors.values_list(['sensor_id', 'sensor__user_full_name'], flat=True)
  File "/home/martin/PycharmProjects/Torque/venv/lib/python3.8/site-packages/django/db/models/query.py", line 851, in values_list
    field_names = {f for f in fields if not hasattr(f, 'resolve_expression')}
  File "/home/martin/PycharmProjects/Torque/venv/lib/python3.8/site-packages/django/db/models/query.py", line 851, in <setcomp>
    field_names = {f for f in fields if not hasattr(f, 'resolve_expression')}
TypeError: unhashable type: 'list'
INFO:django.utils.autoreload:/home/martin/PycharmProjects/Torque/models/views.py changed, reloading.
INFO:django.utils.autoreload:/home/martin/PycharmProjects/Torque/models/views.py changed, reloading.
INFO:django.utils.autoreload:/home/martin/PycharmProjects/Torque/models/views.py changed, reloading.
ERROR:django.request:Internal Server Error: /sensor_from_session/66/
Traceback (most recent call last):
  File "/home/martin/PycharmProjects/Torque/venv/lib/python3.8/site-packages/django/core/handlers/exception.py", line 47, in inner
    response = get_response(request)
  File "/home/martin/PycharmProjects/Torque/venv/lib/python3.8/site-packages/django/core/handlers/base.py", line 181, in _get_response
    response = wrapped_callback(request, *callback_args, **callback_kwargs)
  File "/home/martin/PycharmProjects/Torque/models/views.py", line 459, in obtain_sensors_from_session
    sensors = sensors.values(['sensor__user_full_name', 'sensor_id'], flat=True)
  File "/home/martin/PycharmProjects/Torque/venv/lib/python3.8/site-packages/django/db/models/query.py", line 841, in values
    clone = self._values(*fields, **expressions)
  File "/home/martin/PycharmProjects/Torque/venv/lib/python3.8/site-packages/django/db/models/query.py", line 834, in _values
    clone = clone.annotate(**expressions)
  File "/home/martin/PycharmProjects/Torque/venv/lib/python3.8/site-packages/django/db/models/query.py", line 1087, in annotate
    self._validate_values_are_expressions(args + tuple(kwargs.values()), method_name='annotate')
  File "/home/martin/PycharmProjects/Torque/venv/lib/python3.8/site-packages/django/db/models/query.py", line 1373, in _validate_values_are_expressions
    raise TypeError(
TypeError: QuerySet.annotate() received non-expression(s): True.
INFO:django.utils.autoreload:/home/martin/PycharmProjects/Torque/models/views.py changed, reloading.
INFO:django.utils.autoreload:/home/martin/PycharmProjects/Torque/models/views.py changed, reloading.
ERROR:django.request:Internal Server Error: /sensor_from_session/66/
Traceback (most recent call last):
  File "/home/martin/PycharmProjects/Torque/venv/lib/python3.8/site-packages/django/core/handlers/exception.py", line 47, in inner
    response = get_response(request)
  File "/home/martin/PycharmProjects/Torque/venv/lib/python3.8/site-packages/django/core/handlers/base.py", line 181, in _get_response
    response = wrapped_callback(request, *callback_args, **callback_kwargs)
  File "/home/martin/PycharmProjects/Torque/models/views.py", line 459, in obtain_sensors_from_session
    sensors = sensors.values_list({'sensor__user_full_name', 'sensor_id'}, flat=True)
  File "/home/martin/PycharmProjects/Torque/venv/lib/python3.8/site-packages/django/db/models/query.py", line 851, in values_list
    field_names = {f for f in fields if not hasattr(f, 'resolve_expression')}
  File "/home/martin/PycharmProjects/Torque/venv/lib/python3.8/site-packages/django/db/models/query.py", line 851, in <setcomp>
    field_names = {f for f in fields if not hasattr(f, 'resolve_expression')}
TypeError: unhashable type: 'set'
INFO:django.utils.autoreload:/home/martin/PycharmProjects/Torque/models/views.py changed, reloading.
ERROR:django.request:Internal Server Error: /sensor_from_session/81/
Traceback (most recent call last):
  File "/home/martin/PycharmProjects/Torque/venv/lib/python3.8/site-packages/django/core/handlers/exception.py", line 47, in inner
    response = get_response(request)
  File "/home/martin/PycharmProjects/Torque/venv/lib/python3.8/site-packages/django/core/handlers/base.py", line 181, in _get_response
    response = wrapped_callback(request, *callback_args, **callback_kwargs)
  File "/home/martin/PycharmProjects/Torque/models/views.py", line 459, in obtain_sensors_from_session
    sensors = sensors.values_list(('sensor__user_full_name', 'sensor_id'), flat=True)
  File "/home/martin/PycharmProjects/Torque/venv/lib/python3.8/site-packages/django/db/models/query.py", line 868, in values_list
    clone = self._values(*_fields, **expressions)
  File "/home/martin/PycharmProjects/Torque/venv/lib/python3.8/site-packages/django/db/models/query.py", line 836, in _values
    clone.query.set_values(fields)
  File "/home/martin/PycharmProjects/Torque/venv/lib/python3.8/site-packages/django/db/models/sql/query.py", line 2174, in set_values
    self.add_fields(field_names, True)
  File "/home/martin/PycharmProjects/Torque/venv/lib/python3.8/site-packages/django/db/models/sql/query.py", line 1863, in add_fields
    join_info = self.setup_joins(name.split(LOOKUP_SEP), opts, alias, allow_many=allow_m2m)
AttributeError: 'tuple' object has no attribute 'split'
INFO:django.utils.autoreload:/home/martin/PycharmProjects/Torque/models/views.py changed, reloading.
ERROR:django.request:Internal Server Error: /sensor_from_session/213/
Traceback (most recent call last):
  File "/home/martin/PycharmProjects/Torque/venv/lib/python3.8/site-packages/django/core/handlers/exception.py", line 47, in inner
    response = get_response(request)
  File "/home/martin/PycharmProjects/Torque/venv/lib/python3.8/site-packages/django/core/handlers/base.py", line 181, in _get_response
    response = wrapped_callback(request, *callback_args, **callback_kwargs)
  File "/home/martin/PycharmProjects/Torque/models/views.py", line 459, in obtain_sensors_from_session
    sensors = sensors.values_list(('sensor__user_full_name', 'sensor_id'), flat=True)
  File "/home/martin/PycharmProjects/Torque/venv/lib/python3.8/site-packages/django/db/models/query.py", line 868, in values_list
    clone = self._values(*_fields, **expressions)
  File "/home/martin/PycharmProjects/Torque/venv/lib/python3.8/site-packages/django/db/models/query.py", line 836, in _values
    clone.query.set_values(fields)
  File "/home/martin/PycharmProjects/Torque/venv/lib/python3.8/site-packages/django/db/models/sql/query.py", line 2174, in set_values
    self.add_fields(field_names, True)
  File "/home/martin/PycharmProjects/Torque/venv/lib/python3.8/site-packages/django/db/models/sql/query.py", line 1863, in add_fields
    join_info = self.setup_joins(name.split(LOOKUP_SEP), opts, alias, allow_many=allow_m2m)
AttributeError: 'tuple' object has no attribute 'split'
INFO:django.utils.autoreload:/home/martin/PycharmProjects/Torque/models/views.py changed, reloading.
ERROR:django.request:Internal Server Error: /sensor_from_session/280/
Traceback (most recent call last):
  File "/home/martin/PycharmProjects/Torque/venv/lib/python3.8/site-packages/django/core/handlers/exception.py", line 47, in inner
    response = get_response(request)
  File "/home/martin/PycharmProjects/Torque/venv/lib/python3.8/site-packages/django/core/handlers/base.py", line 181, in _get_response
    response = wrapped_callback(request, *callback_args, **callback_kwargs)
  File "/home/martin/PycharmProjects/Torque/models/views.py", line 459, in obtain_sensors_from_session
    sensors = sensors.values_list(['sensor__user_full_name', 'sensor_id'], flat=True)
  File "/home/martin/PycharmProjects/Torque/venv/lib/python3.8/site-packages/django/db/models/query.py", line 851, in values_list
    field_names = {f for f in fields if not hasattr(f, 'resolve_expression')}
  File "/home/martin/PycharmProjects/Torque/venv/lib/python3.8/site-packages/django/db/models/query.py", line 851, in <setcomp>
    field_names = {f for f in fields if not hasattr(f, 'resolve_expression')}
TypeError: unhashable type: 'list'
INFO:django.utils.autoreload:/home/martin/PycharmProjects/Torque/models/views.py changed, reloading.
INFO:django.utils.autoreload:/home/martin/PycharmProjects/Torque/models/views.py changed, reloading.
ERROR:django.request:Internal Server Error: /sensor_from_session/213/
Traceback (most recent call last):
  File "/home/martin/PycharmProjects/Torque/venv/lib/python3.8/site-packages/django/core/handlers/exception.py", line 47, in inner
    response = get_response(request)
  File "/home/martin/PycharmProjects/Torque/venv/lib/python3.8/site-packages/django/core/handlers/base.py", line 181, in _get_response
    response = wrapped_callback(request, *callback_args, **callback_kwargs)
  File "/home/martin/PycharmProjects/Torque/models/views.py", line 456, in obtain_sensors_from_session
    sensors = records.values(['sensor_id', 'sensor__user_full_name']).distinct().order_by('sensor_id')
  File "/home/martin/PycharmProjects/Torque/venv/lib/python3.8/site-packages/django/db/models/query.py", line 841, in values
    clone = self._values(*fields, **expressions)
  File "/home/martin/PycharmProjects/Torque/venv/lib/python3.8/site-packages/django/db/models/query.py", line 836, in _values
    clone.query.set_values(fields)
  File "/home/martin/PycharmProjects/Torque/venv/lib/python3.8/site-packages/django/db/models/sql/query.py", line 2151, in set_values
    selected = frozenset(field_names + extra_names + annotation_names)
TypeError: unhashable type: 'list'
INFO:django.utils.autoreload:/home/martin/PycharmProjects/Torque/models/views.py changed, reloading.
ERROR:django.request:Internal Server Error: /sensor_from_session/213/
Traceback (most recent call last):
  File "/home/martin/PycharmProjects/Torque/venv/lib/python3.8/site-packages/django/core/handlers/exception.py", line 47, in inner
    response = get_response(request)
  File "/home/martin/PycharmProjects/Torque/venv/lib/python3.8/site-packages/django/core/handlers/base.py", line 181, in _get_response
    response = wrapped_callback(request, *callback_args, **callback_kwargs)
  File "/home/martin/PycharmProjects/Torque/models/views.py", line 456, in obtain_sensors_from_session
    sensors = records.values(['sensor_id', 'sensor__user_full_name']).distinct().order_by('sensor_id')
  File "/home/martin/PycharmProjects/Torque/venv/lib/python3.8/site-packages/django/db/models/query.py", line 841, in values
    clone = self._values(*fields, **expressions)
  File "/home/martin/PycharmProjects/Torque/venv/lib/python3.8/site-packages/django/db/models/query.py", line 836, in _values
    clone.query.set_values(fields)
  File "/home/martin/PycharmProjects/Torque/venv/lib/python3.8/site-packages/django/db/models/sql/query.py", line 2151, in set_values
    selected = frozenset(field_names + extra_names + annotation_names)
TypeError: unhashable type: 'list'
INFO:django.utils.autoreload:/home/martin/PycharmProjects/Torque/models/views.py changed, reloading.
ERROR:django.request:Internal Server Error: /sensor_from_session/300/
Traceback (most recent call last):
  File "/home/martin/PycharmProjects/Torque/venv/lib/python3.8/site-packages/django/core/handlers/exception.py", line 47, in inner
    response = get_response(request)
  File "/home/martin/PycharmProjects/Torque/venv/lib/python3.8/site-packages/django/core/handlers/base.py", line 181, in _get_response
    response = wrapped_callback(request, *callback_args, **callback_kwargs)
  File "/home/martin/PycharmProjects/Torque/models/views.py", line 456, in obtain_sensors_from_session
    sensors = records.values_list(['sensor_id', 'sensor__user_full_name']).distinct().order_by('sensor_id')
  File "/home/martin/PycharmProjects/Torque/venv/lib/python3.8/site-packages/django/db/models/query.py", line 851, in values_list
    field_names = {f for f in fields if not hasattr(f, 'resolve_expression')}
  File "/home/martin/PycharmProjects/Torque/venv/lib/python3.8/site-packages/django/db/models/query.py", line 851, in <setcomp>
    field_names = {f for f in fields if not hasattr(f, 'resolve_expression')}
TypeError: unhashable type: 'list'
WARNING:django.request:Not Found: /favicon.ico
INFO:django.utils.autoreload:/home/martin/PycharmProjects/Torque/models/views.py changed, reloading.
ERROR:django.request:Internal Server Error: /sensor_from_session/213/
Traceback (most recent call last):
  File "/home/martin/PycharmProjects/Torque/venv/lib/python3.8/site-packages/django/core/handlers/exception.py", line 47, in inner
    response = get_response(request)
  File "/home/martin/PycharmProjects/Torque/venv/lib/python3.8/site-packages/django/core/handlers/base.py", line 181, in _get_response
    response = wrapped_callback(request, *callback_args, **callback_kwargs)
  File "/home/martin/PycharmProjects/Torque/models/views.py", line 457, in obtain_sensors_from_session
    print(sensors.query)
  File "/home/martin/PycharmProjects/Torque/venv/lib/python3.8/site-packages/django/db/models/sql/query.py", line 256, in __str__
    sql, params = self.sql_with_params()
  File "/home/martin/PycharmProjects/Torque/venv/lib/python3.8/site-packages/django/db/models/sql/query.py", line 264, in sql_with_params
    return self.get_compiler(DEFAULT_DB_ALIAS).as_sql()
  File "/home/martin/PycharmProjects/Torque/venv/lib/python3.8/site-packages/django/db/models/sql/compiler.py", line 519, in as_sql
    distinct_result, distinct_params = self.connection.ops.distinct_sql(
  File "/home/martin/PycharmProjects/Torque/venv/lib/python3.8/site-packages/django/db/backends/base/operations.py", line 176, in distinct_sql
    raise NotSupportedError('DISTINCT ON fields is not supported by this database backend')
django.db.utils.NotSupportedError: DISTINCT ON fields is not supported by this database backend
INFO:django.utils.autoreload:/home/martin/PycharmProjects/Torque/models/views.py changed, reloading.
INFO:django.utils.autoreload:/home/martin/PycharmProjects/Torque/models/views.py changed, reloading.
ERROR:django.request:Internal Server Error: /sensor_from_session/213/
Traceback (most recent call last):
  File "/home/martin/PycharmProjects/Torque/venv/lib/python3.8/site-packages/django/core/handlers/exception.py", line 47, in inner
    response = get_response(request)
  File "/home/martin/PycharmProjects/Torque/venv/lib/python3.8/site-packages/django/core/handlers/base.py", line 181, in _get_response
    response = wrapped_callback(request, *callback_args, **callback_kwargs)
  File "/home/martin/PycharmProjects/Torque/models/views.py", line 459, in obtain_sensors_from_session
    sensors = sensors.values_list('sensor__user_full_name', 'sensor_id', flat=True)
  File "/home/martin/PycharmProjects/Torque/venv/lib/python3.8/site-packages/django/db/models/query.py", line 849, in values_list
    raise TypeError("'flat' is not valid when values_list is called with more than one field.")
TypeError: 'flat' is not valid when values_list is called with more than one field.
INFO:django.utils.autoreload:/home/martin/PycharmProjects/Torque/models/views.py changed, reloading.
INFO:django.utils.autoreload:/home/martin/PycharmProjects/Torque/models/views.py changed, reloading.
INFO:django.utils.autoreload:/home/martin/PycharmProjects/Torque/models/views.py changed, reloading.
INFO:django.utils.autoreload:/home/martin/PycharmProjects/Torque/models/views.py changed, reloading.
INFO:django.utils.autoreload:/home/martin/PycharmProjects/Torque/models/views.py changed, reloading.
WARNING:django.request:Not Found: /favicon.ico
INFO:django.utils.autoreload:/home/martin/PycharmProjects/Torque/models/views.py changed, reloading.
WARNING:django.request:Not Found: /favicon.ico
INFO:django.utils.autoreload:/home/martin/PycharmProjects/Torque/models/views.py changed, reloading.
INFO:django.utils.autoreload:/home/martin/PycharmProjects/Torque/models/views.py changed, reloading.
ERROR:django.request:Internal Server Error: /
Traceback (most recent call last):
  File "/home/martin/PycharmProjects/Torque/venv/lib/python3.8/site-packages/django/core/handlers/exception.py", line 47, in inner
    response = get_response(request)
  File "/home/martin/PycharmProjects/Torque/venv/lib/python3.8/site-packages/django/core/handlers/base.py", line 181, in _get_response
    response = wrapped_callback(request, *callback_args, **callback_kwargs)
  File "/home/martin/PycharmProjects/Torque/models/views.py", line 55, in sessions_by_id_list
    sessions = Log.objects.all().order_by(id)
  File "/home/martin/PycharmProjects/Torque/venv/lib/python3.8/site-packages/django/db/models/query.py", line 1134, in order_by
    obj.query.add_ordering(*field_names)
  File "/home/martin/PycharmProjects/Torque/venv/lib/python3.8/site-packages/django/db/models/sql/query.py", line 1928, in add_ordering
    raise FieldError('Invalid order_by arguments: %s' % errors)
django.core.exceptions.FieldError: Invalid order_by arguments: [<built-in function id>]
ERROR:django.request:Internal Server Error: /
Traceback (most recent call last):
  File "/home/martin/PycharmProjects/Torque/venv/lib/python3.8/site-packages/django/core/handlers/exception.py", line 47, in inner
    response = get_response(request)
  File "/home/martin/PycharmProjects/Torque/venv/lib/python3.8/site-packages/django/core/handlers/base.py", line 181, in _get_response
    response = wrapped_callback(request, *callback_args, **callback_kwargs)
  File "/home/martin/PycharmProjects/Torque/models/views.py", line 55, in sessions_by_id_list
    sessions = Log.objects.all().order_by(id)
  File "/home/martin/PycharmProjects/Torque/venv/lib/python3.8/site-packages/django/db/models/query.py", line 1134, in order_by
    obj.query.add_ordering(*field_names)
  File "/home/martin/PycharmProjects/Torque/venv/lib/python3.8/site-packages/django/db/models/sql/query.py", line 1928, in add_ordering
    raise FieldError('Invalid order_by arguments: %s' % errors)
django.core.exceptions.FieldError: Invalid order_by arguments: [<built-in function id>]
INFO:django.utils.autoreload:/home/martin/PycharmProjects/Torque/models/views.py changed, reloading.
INFO:django.utils.autoreload:/home/martin/PycharmProjects/Torque/models/views.py changed, reloading.
INFO:django.utils.autoreload:/home/martin/PycharmProjects/Torque/models/views.py changed, reloading.
INFO:django.utils.autoreload:/home/martin/PycharmProjects/Torque/models/views.py changed, reloading.
INFO:django.utils.autoreload:/home/martin/PycharmProjects/Torque/models/views.py changed, reloading.
WARNING:django.request:Not Found: /sensor_from_session/
WARNING:django.request:Not Found: /generate_csv/
INFO:django.utils.autoreload:/home/martin/PycharmProjects/Torque/Torque/urls.py changed, reloading.
WARNING:django.security.csrf:Forbidden (CSRF token missing or incorrect.): /generate_csv/
WARNING:django.security.csrf:Forbidden (CSRF token missing or incorrect.): /generate_csv/
WARNING:django.security.csrf:Forbidden (CSRF token missing or incorrect.): /generate_csv/
WARNING:django.security.csrf:Forbidden (CSRF token missing or incorrect.): /generate_csv/
ERROR:django.request:Internal Server Error: /generate_csv/
Traceback (most recent call last):
  File "/home/martin/PycharmProjects/Torque/venv/lib/python3.8/site-packages/django/core/handlers/exception.py", line 47, in inner
    response = get_response(request)
  File "/home/martin/PycharmProjects/Torque/venv/lib/python3.8/site-packages/django/core/handlers/base.py", line 188, in _get_response
    self.check_response(response, callback)
  File "/home/martin/PycharmProjects/Torque/venv/lib/python3.8/site-packages/django/core/handlers/base.py", line 309, in check_response
    raise ValueError(
ValueError: The view models.views.generate_custom_csv didn't return an HttpResponse object. It returned None instead.
WARNING:django.request:Not Found: /favicon.ico
INFO:django.utils.autoreload:/home/martin/PycharmProjects/Torque/models/views.py changed, reloading.
INFO:django.utils.autoreload:/home/martin/PycharmProjects/Torque/models/views.py changed, reloading.
INFO:django.utils.autoreload:/home/martin/PycharmProjects/Torque/models/views.py changed, reloading.
WARNING:django.security.csrf:Forbidden (CSRF token missing or incorrect.): /generate_csv/
WARNING:django.security.csrf:Forbidden (CSRF token missing or incorrect.): /generate_csv/
WARNING:django.security.csrf:Forbidden (CSRF token missing or incorrect.): /generate_csv/
WARNING:django.security.csrf:Forbidden (CSRF token missing or incorrect.): /generate_csv/
WARNING:django.security.csrf:Forbidden (CSRF token missing or incorrect.): /generate_csv/
WARNING:django.security.csrf:Forbidden (CSRF token missing or incorrect.): /generate_csv/
WARNING:django.security.csrf:Forbidden (CSRF token missing or incorrect.): /generate_csv/
WARNING:django.security.csrf:Forbidden (CSRF token missing or incorrect.): /generate_csv/
WARNING:django.security.csrf:Forbidden (CSRF token missing or incorrect.): /generate_csv/
WARNING:django.security.csrf:Forbidden (CSRF token missing or incorrect.): /generate_csv/
WARNING:django.security.csrf:Forbidden (CSRF token missing or incorrect.): /generate_csv/
WARNING:django.security.csrf:Forbidden (CSRF token missing or incorrect.): /generate_csv/
WARNING:django.security.csrf:Forbidden (CSRF token missing or incorrect.): /generate_csv/
WARNING:django.security.csrf:Forbidden (CSRF token missing or incorrect.): /generate_csv/
INFO:django.utils.autoreload:/home/martin/PycharmProjects/Torque/models/views.py changed, reloading.
INFO:django.utils.autoreload:/home/martin/PycharmProjects/Torque/models/views.py changed, reloading.
INFO:django.utils.autoreload:/home/martin/PycharmProjects/Torque/models/views.py changed, reloading.
INFO:django.utils.autoreload:/home/martin/PycharmProjects/Torque/models/views.py changed, reloading.
INFO:django.utils.autoreload:/home/martin/PycharmProjects/Torque/models/views.py changed, reloading.
INFO:django.utils.autoreload:/home/martin/PycharmProjects/Torque/models/views.py changed, reloading.
INFO:django.utils.autoreload:/home/martin/PycharmProjects/Torque/models/views.py changed, reloading.
ERROR:django.request:Internal Server Error: /generate_csv/
Traceback (most recent call last):
  File "/home/martin/PycharmProjects/Torque/venv/lib/python3.8/site-packages/django/core/handlers/exception.py", line 47, in inner
    response = get_response(request)
  File "/home/martin/PycharmProjects/Torque/venv/lib/python3.8/site-packages/django/core/handlers/base.py", line 181, in _get_response
    response = wrapped_callback(request, *callback_args, **callback_kwargs)
  File "/home/martin/PycharmProjects/Torque/venv/lib/python3.8/site-packages/django/views/decorators/csrf.py", line 54, in wrapped_view
    return view_func(*args, **kwargs)
  File "/home/martin/PycharmProjects/Torque/models/views.py", line 473, in generate_custom_csv
    print(request.POST.get(['body']))
  File "/home/martin/PycharmProjects/Torque/venv/lib/python3.8/site-packages/django/utils/datastructures.py", line 116, in get
    val = self[key]
  File "/home/martin/PycharmProjects/Torque/venv/lib/python3.8/site-packages/django/utils/datastructures.py", line 76, in __getitem__
    list_ = super().__getitem__(key)
TypeError: unhashable type: 'list'
INFO:django.utils.autoreload:/home/martin/PycharmProjects/Torque/models/views.py changed, reloading.
INFO:django.utils.autoreload:/home/martin/PycharmProjects/Torque/models/views.py changed, reloading.
INFO:django.utils.autoreload:/home/martin/PycharmProjects/Torque/models/views.py changed, reloading.
INFO:django.utils.autoreload:/home/martin/PycharmProjects/Torque/models/views.py changed, reloading.
INFO:django.utils.autoreload:/home/martin/PycharmProjects/Torque/models/views.py changed, reloading.
INFO:django.utils.autoreload:/home/martin/PycharmProjects/Torque/models/views.py changed, reloading.
INFO:django.utils.autoreload:/home/martin/PycharmProjects/Torque/models/views.py changed, reloading.
INFO:django.utils.autoreload:/home/martin/PycharmProjects/Torque/models/views.py changed, reloading.
INFO:django.utils.autoreload:/home/martin/PycharmProjects/Torque/models/views.py changed, reloading.
INFO:django.utils.autoreload:/home/martin/PycharmProjects/Torque/models/views.py changed, reloading.
INFO:django.utils.autoreload:/home/martin/PycharmProjects/Torque/models/views.py changed, reloading.
ERROR:django.request:Internal Server Error: /generate_csv/
Traceback (most recent call last):
  File "/home/martin/PycharmProjects/Torque/venv/lib/python3.8/site-packages/django/core/handlers/exception.py", line 47, in inner
    response = get_response(request)
  File "/home/martin/PycharmProjects/Torque/venv/lib/python3.8/site-packages/django/core/handlers/base.py", line 181, in _get_response
    response = wrapped_callback(request, *callback_args, **callback_kwargs)
  File "/home/martin/PycharmProjects/Torque/venv/lib/python3.8/site-packages/django/views/decorators/csrf.py", line 54, in wrapped_view
    return view_func(*args, **kwargs)
  File "/home/martin/PycharmProjects/Torque/models/views.py", line 474, in generate_custom_csv
    print(request.body['idSensors'])
TypeError: byte indices must be integers or slices, not str
INFO:django.utils.autoreload:/home/martin/PycharmProjects/Torque/models/views.py changed, reloading.
INFO:django.utils.autoreload:/home/martin/PycharmProjects/Torque/models/views.py changed, reloading.
INFO:django.utils.autoreload:/home/martin/PycharmProjects/Torque/models/views.py changed, reloading.
INFO:django.utils.autoreload:/home/martin/PycharmProjects/Torque/models/views.py changed, reloading.
INFO:django.utils.autoreload:/home/martin/PycharmProjects/Torque/models/views.py changed, reloading.
ERROR:django.request:Internal Server Error: /generate_csv/
Traceback (most recent call last):
  File "/home/martin/PycharmProjects/Torque/venv/lib/python3.8/site-packages/django/core/handlers/exception.py", line 47, in inner
    response = get_response(request)
  File "/home/martin/PycharmProjects/Torque/venv/lib/python3.8/site-packages/django/core/handlers/base.py", line 181, in _get_response
    response = wrapped_callback(request, *callback_args, **callback_kwargs)
  File "/home/martin/PycharmProjects/Torque/venv/lib/python3.8/site-packages/django/views/decorators/csrf.py", line 54, in wrapped_view
    return view_func(*args, **kwargs)
  File "/home/martin/PycharmProjects/Torque/models/views.py", line 472, in generate_custom_csv
    print(request.body('idSensors'))
TypeError: 'bytes' object is not callable
ERROR:django.request:Internal Server Error: /generate_csv/
Traceback (most recent call last):
  File "/home/martin/PycharmProjects/Torque/venv/lib/python3.8/site-packages/django/core/handlers/exception.py", line 47, in inner
    response = get_response(request)
  File "/home/martin/PycharmProjects/Torque/venv/lib/python3.8/site-packages/django/core/handlers/base.py", line 181, in _get_response
    response = wrapped_callback(request, *callback_args, **callback_kwargs)
  File "/home/martin/PycharmProjects/Torque/venv/lib/python3.8/site-packages/django/views/decorators/csrf.py", line 54, in wrapped_view
    return view_func(*args, **kwargs)
  File "/home/martin/PycharmProjects/Torque/models/views.py", line 472, in generate_custom_csv
    print(request.body('idSensors'))
TypeError: 'bytes' object is not callable
INFO:django.utils.autoreload:/home/martin/PycharmProjects/Torque/models/views.py changed, reloading.
INFO:django.utils.autoreload:/home/martin/PycharmProjects/Torque/models/views.py changed, reloading.
INFO:django.utils.autoreload:/home/martin/PycharmProjects/Torque/models/views.py changed, reloading.
ERROR:django.request:Internal Server Error: /generate_csv/
Traceback (most recent call last):
  File "/home/martin/PycharmProjects/Torque/venv/lib/python3.8/site-packages/django/core/handlers/exception.py", line 47, in inner
    response = get_response(request)
  File "/home/martin/PycharmProjects/Torque/venv/lib/python3.8/site-packages/django/core/handlers/base.py", line 181, in _get_response
    response = wrapped_callback(request, *callback_args, **callback_kwargs)
  File "/home/martin/PycharmProjects/Torque/venv/lib/python3.8/site-packages/django/views/decorators/csrf.py", line 54, in wrapped_view
    return view_func(*args, **kwargs)
  File "/home/martin/PycharmProjects/Torque/models/views.py", line 472, in generate_custom_csv
    print(request.body('idSensors'))
TypeError: 'bytes' object is not callable
ERROR:django.request:Internal Server Error: /generate_csv/
Traceback (most recent call last):
  File "/home/martin/PycharmProjects/Torque/venv/lib/python3.8/site-packages/django/core/handlers/exception.py", line 47, in inner
    response = get_response(request)
  File "/home/martin/PycharmProjects/Torque/venv/lib/python3.8/site-packages/django/core/handlers/base.py", line 181, in _get_response
    response = wrapped_callback(request, *callback_args, **callback_kwargs)
  File "/home/martin/PycharmProjects/Torque/venv/lib/python3.8/site-packages/django/views/decorators/csrf.py", line 54, in wrapped_view
    return view_func(*args, **kwargs)
  File "/home/martin/PycharmProjects/Torque/models/views.py", line 472, in generate_custom_csv
    print(request.body('idSensors'))
TypeError: 'bytes' object is not callable
INFO:django.utils.autoreload:/home/martin/PycharmProjects/Torque/models/views.py changed, reloading.
INFO:django.utils.autoreload:/home/martin/PycharmProjects/Torque/models/views.py changed, reloading.
INFO:django.utils.autoreload:/home/martin/PycharmProjects/Torque/models/views.py changed, reloading.
INFO:django.utils.autoreload:/home/martin/PycharmProjects/Torque/models/views.py changed, reloading.
INFO:django.utils.autoreload:/home/martin/PycharmProjects/Torque/models/views.py changed, reloading.
INFO:django.utils.autoreload:/home/martin/PycharmProjects/Torque/models/views.py changed, reloading.
INFO:django.utils.autoreload:/home/martin/PycharmProjects/Torque/models/views.py changed, reloading.
INFO:django.utils.autoreload:/home/martin/PycharmProjects/Torque/models/views.py changed, reloading.
INFO:django.utils.autoreload:/home/martin/PycharmProjects/Torque/models/views.py changed, reloading.
INFO:django.utils.autoreload:/home/martin/PycharmProjects/Torque/models/views.py changed, reloading.
INFO:django.utils.autoreload:/home/martin/PycharmProjects/Torque/models/views.py changed, reloading.
INFO:django.utils.autoreload:/home/martin/PycharmProjects/Torque/models/views.py changed, reloading.
INFO:django.utils.autoreload:/home/martin/PycharmProjects/Torque/models/views.py changed, reloading.
INFO:django.utils.autoreload:/home/martin/PycharmProjects/Torque/models/views.py changed, reloading.
INFO:django.utils.autoreload:/home/martin/PycharmProjects/Torque/models/views.py changed, reloading.
INFO:django.utils.autoreload:/home/martin/PycharmProjects/Torque/models/views.py changed, reloading.
INFO:django.utils.autoreload:/home/martin/PycharmProjects/Torque/models/views.py changed, reloading.
INFO:django.utils.autoreload:/home/martin/PycharmProjects/Torque/models/views.py changed, reloading.
INFO:django.utils.autoreload:/home/martin/PycharmProjects/Torque/models/views.py changed, reloading.
INFO:django.utils.autoreload:/home/martin/PycharmProjects/Torque/models/views.py changed, reloading.
INFO:django.utils.autoreload:/home/martin/PycharmProjects/Torque/models/views.py changed, reloading.
INFO:django.utils.autoreload:/home/martin/PycharmProjects/Torque/models/views.py changed, reloading.
INFO:django.utils.autoreload:/home/martin/PycharmProjects/Torque/models/views.py changed, reloading.
ERROR:django.request:Internal Server Error: /generate_csv/
Traceback (most recent call last):
  File "/home/martin/PycharmProjects/Torque/venv/lib/python3.8/site-packages/django/core/handlers/exception.py", line 47, in inner
    response = get_response(request)
  File "/home/martin/PycharmProjects/Torque/venv/lib/python3.8/site-packages/django/core/handlers/base.py", line 181, in _get_response
    response = wrapped_callback(request, *callback_args, **callback_kwargs)
  File "/home/martin/PycharmProjects/Torque/venv/lib/python3.8/site-packages/django/views/decorators/csrf.py", line 54, in wrapped_view
    return view_func(*args, **kwargs)
  File "/home/martin/PycharmProjects/Torque/models/views.py", line 479, in generate_custom_csv
    sensor_name = Sensor.objects.get(id=id_session)
  File "/home/martin/PycharmProjects/Torque/venv/lib/python3.8/site-packages/django/db/models/manager.py", line 85, in manager_method
    return getattr(self.get_queryset(), name)(*args, **kwargs)
  File "/home/martin/PycharmProjects/Torque/venv/lib/python3.8/site-packages/django/db/models/query.py", line 429, in get
    raise self.model.DoesNotExist(
models.models.Sensor.DoesNotExist: Sensor matching query does not exist.
INFO:django.utils.autoreload:/home/martin/PycharmProjects/Torque/models/views.py changed, reloading.
INFO:django.utils.autoreload:/home/martin/PycharmProjects/Torque/models/views.py changed, reloading.
INFO:django.utils.autoreload:/home/martin/PycharmProjects/Torque/models/views.py changed, reloading.
INFO:django.utils.autoreload:/home/martin/PycharmProjects/Torque/models/views.py changed, reloading.
INFO:django.utils.autoreload:/home/martin/PycharmProjects/Torque/models/views.py changed, reloading.
INFO:django.utils.autoreload:/home/martin/PycharmProjects/Torque/models/views.py changed, reloading.
ERROR:django.request:Internal Server Error: /generate_csv/
Traceback (most recent call last):
  File "/home/martin/PycharmProjects/Torque/venv/lib/python3.8/site-packages/django/core/handlers/exception.py", line 47, in inner
    response = get_response(request)
  File "/home/martin/PycharmProjects/Torque/venv/lib/python3.8/site-packages/django/core/handlers/base.py", line 181, in _get_response
    response = wrapped_callback(request, *callback_args, **callback_kwargs)
  File "/home/martin/PycharmProjects/Torque/venv/lib/python3.8/site-packages/django/views/decorators/csrf.py", line 54, in wrapped_view
    return view_func(*args, **kwargs)
  File "/home/martin/PycharmProjects/Torque/models/views.py", line 482, in generate_custom_csv
    values = log.record_set.filter(sensor_id=id_sensor).values('value', flat=True)
  File "/home/martin/PycharmProjects/Torque/venv/lib/python3.8/site-packages/django/db/models/query.py", line 841, in values
    clone = self._values(*fields, **expressions)
  File "/home/martin/PycharmProjects/Torque/venv/lib/python3.8/site-packages/django/db/models/query.py", line 834, in _values
    clone = clone.annotate(**expressions)
  File "/home/martin/PycharmProjects/Torque/venv/lib/python3.8/site-packages/django/db/models/query.py", line 1087, in annotate
    self._validate_values_are_expressions(args + tuple(kwargs.values()), method_name='annotate')
  File "/home/martin/PycharmProjects/Torque/venv/lib/python3.8/site-packages/django/db/models/query.py", line 1373, in _validate_values_are_expressions
    raise TypeError(
TypeError: QuerySet.annotate() received non-expression(s): True.
INFO:django.utils.autoreload:/home/martin/PycharmProjects/Torque/models/views.py changed, reloading.
INFO:django.utils.autoreload:/home/martin/PycharmProjects/Torque/models/views.py changed, reloading.
INFO:django.utils.autoreload:/home/martin/PycharmProjects/Torque/models/views.py changed, reloading.
INFO:django.utils.autoreload:/home/martin/PycharmProjects/Torque/models/views.py changed, reloading.
INFO:django.utils.autoreload:/home/martin/PycharmProjects/Torque/models/views.py changed, reloading.
INFO:django.utils.autoreload:/home/martin/PycharmProjects/Torque/models/views.py changed, reloading.
INFO:django.utils.autoreload:/home/martin/PycharmProjects/Torque/models/views.py changed, reloading.
INFO:django.utils.autoreload:/home/martin/PycharmProjects/Torque/models/views.py changed, reloading.
ERROR:django.request:Internal Server Error: /generate_csv/
Traceback (most recent call last):
  File "/home/martin/PycharmProjects/Torque/venv/lib/python3.8/site-packages/django/core/handlers/exception.py", line 47, in inner
    response = get_response(request)
  File "/home/martin/PycharmProjects/Torque/venv/lib/python3.8/site-packages/django/core/handlers/base.py", line 181, in _get_response
    response = wrapped_callback(request, *callback_args, **callback_kwargs)
  File "/home/martin/PycharmProjects/Torque/venv/lib/python3.8/site-packages/django/views/decorators/csrf.py", line 54, in wrapped_view
    return view_func(*args, **kwargs)
  File "/home/martin/PycharmProjects/Torque/models/views.py", line 483, in generate_custom_csv
    print(list(float(values)))
TypeError: float() argument must be a string or a number, not 'QuerySet'
INFO:django.utils.autoreload:/home/martin/PycharmProjects/Torque/models/views.py changed, reloading.
INFO:django.utils.autoreload:/home/martin/PycharmProjects/Torque/models/views.py changed, reloading.
INFO:django.utils.autoreload:/home/martin/PycharmProjects/Torque/models/views.py changed, reloading.
INFO:django.utils.autoreload:/home/martin/PycharmProjects/Torque/models/views.py changed, reloading.
INFO:django.utils.autoreload:/home/martin/PycharmProjects/Torque/models/views.py changed, reloading.
INFO:django.utils.autoreload:/home/martin/PycharmProjects/Torque/models/views.py changed, reloading.
INFO:django.utils.autoreload:/home/martin/PycharmProjects/Torque/models/views.py changed, reloading.
INFO:django.utils.autoreload:/home/martin/PycharmProjects/Torque/models/views.py changed, reloading.
INFO:django.utils.autoreload:/home/martin/PycharmProjects/Torque/models/views.py changed, reloading.
ERROR:django.request:Internal Server Error: /generate_csv/
Traceback (most recent call last):
  File "/home/martin/PycharmProjects/Torque/venv/lib/python3.8/site-packages/django/core/handlers/exception.py", line 47, in inner
    response = get_response(request)
  File "/home/martin/PycharmProjects/Torque/venv/lib/python3.8/site-packages/django/core/handlers/base.py", line 181, in _get_response
    response = wrapped_callback(request, *callback_args, **callback_kwargs)
  File "/home/martin/PycharmProjects/Torque/venv/lib/python3.8/site-packages/django/views/decorators/csrf.py", line 54, in wrapped_view
    return view_func(*args, **kwargs)
  File "/home/martin/PycharmProjects/Torque/models/views.py", line 490, in generate_custom_csv
    dataframe[i] = list(values)
  File "/home/martin/PycharmProjects/Torque/venv/lib/python3.8/site-packages/pandas/core/frame.py", line 3163, in __setitem__
    self._set_item(key, value)
  File "/home/martin/PycharmProjects/Torque/venv/lib/python3.8/site-packages/pandas/core/frame.py", line 3242, in _set_item
    value = self._sanitize_column(key, value)
  File "/home/martin/PycharmProjects/Torque/venv/lib/python3.8/site-packages/pandas/core/frame.py", line 3899, in _sanitize_column
    value = sanitize_index(value, self.index)
  File "/home/martin/PycharmProjects/Torque/venv/lib/python3.8/site-packages/pandas/core/internals/construction.py", line 751, in sanitize_index
    raise ValueError(
ValueError: Length of values (1113) does not match length of index (1065)
INFO:django.utils.autoreload:/home/martin/PycharmProjects/Torque/models/views.py changed, reloading.
INFO:django.utils.autoreload:/home/martin/PycharmProjects/Torque/models/views.py changed, reloading.
ERROR:django.request:Internal Server Error: /generate_csv/
Traceback (most recent call last):
  File "/home/martin/PycharmProjects/Torque/venv/lib/python3.8/site-packages/django/core/handlers/exception.py", line 47, in inner
    response = get_response(request)
  File "/home/martin/PycharmProjects/Torque/venv/lib/python3.8/site-packages/django/core/handlers/base.py", line 181, in _get_response
    response = wrapped_callback(request, *callback_args, **callback_kwargs)
  File "/home/martin/PycharmProjects/Torque/venv/lib/python3.8/site-packages/django/views/decorators/csrf.py", line 54, in wrapped_view
    return view_func(*args, **kwargs)
  File "/home/martin/PycharmProjects/Torque/models/views.py", line 490, in generate_custom_csv
    dataframe[i] = list(values)
  File "/home/martin/PycharmProjects/Torque/venv/lib/python3.8/site-packages/pandas/core/frame.py", line 3163, in __setitem__
    self._set_item(key, value)
  File "/home/martin/PycharmProjects/Torque/venv/lib/python3.8/site-packages/pandas/core/frame.py", line 3242, in _set_item
    value = self._sanitize_column(key, value)
  File "/home/martin/PycharmProjects/Torque/venv/lib/python3.8/site-packages/pandas/core/frame.py", line 3899, in _sanitize_column
    value = sanitize_index(value, self.index)
  File "/home/martin/PycharmProjects/Torque/venv/lib/python3.8/site-packages/pandas/core/internals/construction.py", line 751, in sanitize_index
    raise ValueError(
ValueError: Length of values (1113) does not match length of index (1065)
INFO:django.utils.autoreload:/home/martin/PycharmProjects/Torque/models/views.py changed, reloading.
ERROR:django.request:Internal Server Error: /generate_csv/
Traceback (most recent call last):
  File "/home/martin/PycharmProjects/Torque/venv/lib/python3.8/site-packages/django/core/handlers/exception.py", line 47, in inner
    response = get_response(request)
  File "/home/martin/PycharmProjects/Torque/venv/lib/python3.8/site-packages/django/core/handlers/base.py", line 181, in _get_response
    response = wrapped_callback(request, *callback_args, **callback_kwargs)
  File "/home/martin/PycharmProjects/Torque/venv/lib/python3.8/site-packages/django/views/decorators/csrf.py", line 54, in wrapped_view
    return view_func(*args, **kwargs)
  File "/home/martin/PycharmProjects/Torque/models/views.py", line 490, in generate_custom_csv
    dataframe[columns[i]] = list(values)
  File "/home/martin/PycharmProjects/Torque/venv/lib/python3.8/site-packages/pandas/core/frame.py", line 3163, in __setitem__
    self._set_item(key, value)
  File "/home/martin/PycharmProjects/Torque/venv/lib/python3.8/site-packages/pandas/core/frame.py", line 3242, in _set_item
    value = self._sanitize_column(key, value)
  File "/home/martin/PycharmProjects/Torque/venv/lib/python3.8/site-packages/pandas/core/frame.py", line 3899, in _sanitize_column
    value = sanitize_index(value, self.index)
  File "/home/martin/PycharmProjects/Torque/venv/lib/python3.8/site-packages/pandas/core/internals/construction.py", line 751, in sanitize_index
    raise ValueError(
ValueError: Length of values (1113) does not match length of index (1065)
INFO:django.utils.autoreload:/home/martin/PycharmProjects/Torque/models/views.py changed, reloading.
INFO:django.utils.autoreload:/home/martin/PycharmProjects/Torque/models/views.py changed, reloading.
ERROR:django.request:Internal Server Error: /generate_csv/
Traceback (most recent call last):
  File "/home/martin/PycharmProjects/Torque/venv/lib/python3.8/site-packages/django/core/handlers/exception.py", line 47, in inner
    response = get_response(request)
  File "/home/martin/PycharmProjects/Torque/venv/lib/python3.8/site-packages/django/core/handlers/base.py", line 181, in _get_response
    response = wrapped_callback(request, *callback_args, **callback_kwargs)
  File "/home/martin/PycharmProjects/Torque/venv/lib/python3.8/site-packages/django/views/decorators/csrf.py", line 54, in wrapped_view
    return view_func(*args, **kwargs)
  File "/home/martin/PycharmProjects/Torque/models/views.py", line 483, in generate_custom_csv
    dataframe.columns = columns
  File "/home/martin/PycharmProjects/Torque/venv/lib/python3.8/site-packages/pandas/core/generic.py", line 5478, in __setattr__
    return object.__setattr__(self, name, value)
  File "pandas/_libs/properties.pyx", line 66, in pandas._libs.properties.AxisProperty.__set__
  File "/home/martin/PycharmProjects/Torque/venv/lib/python3.8/site-packages/pandas/core/generic.py", line 670, in _set_axis
    self._mgr.set_axis(axis, labels)
  File "/home/martin/PycharmProjects/Torque/venv/lib/python3.8/site-packages/pandas/core/internals/managers.py", line 220, in set_axis
    raise ValueError(
ValueError: Length mismatch: Expected axis has 0 elements, new values have 4 elements
INFO:django.utils.autoreload:/home/martin/PycharmProjects/Torque/models/views.py changed, reloading.
INFO:django.utils.autoreload:/home/martin/PycharmProjects/Torque/models/views.py changed, reloading.
ERROR:django.request:Internal Server Error: /generate_csv/
Traceback (most recent call last):
  File "/home/martin/PycharmProjects/Torque/venv/lib/python3.8/site-packages/django/core/handlers/exception.py", line 47, in inner
    response = get_response(request)
  File "/home/martin/PycharmProjects/Torque/venv/lib/python3.8/site-packages/django/core/handlers/base.py", line 181, in _get_response
    response = wrapped_callback(request, *callback_args, **callback_kwargs)
  File "/home/martin/PycharmProjects/Torque/venv/lib/python3.8/site-packages/django/views/decorators/csrf.py", line 54, in wrapped_view
    return view_func(*args, **kwargs)
  File "/home/martin/PycharmProjects/Torque/models/views.py", line 490, in generate_custom_csv
    dataframe[i] = list(values)
  File "/home/martin/PycharmProjects/Torque/venv/lib/python3.8/site-packages/pandas/core/frame.py", line 3163, in __setitem__
    self._set_item(key, value)
  File "/home/martin/PycharmProjects/Torque/venv/lib/python3.8/site-packages/pandas/core/frame.py", line 3242, in _set_item
    value = self._sanitize_column(key, value)
  File "/home/martin/PycharmProjects/Torque/venv/lib/python3.8/site-packages/pandas/core/frame.py", line 3899, in _sanitize_column
    value = sanitize_index(value, self.index)
  File "/home/martin/PycharmProjects/Torque/venv/lib/python3.8/site-packages/pandas/core/internals/construction.py", line 751, in sanitize_index
    raise ValueError(
ValueError: Length of values (1113) does not match length of index (1065)
INFO:django.utils.autoreload:/home/martin/PycharmProjects/Torque/models/views.py changed, reloading.
ERROR:django.request:Internal Server Error: /generate_csv/
Traceback (most recent call last):
  File "/home/martin/PycharmProjects/Torque/venv/lib/python3.8/site-packages/django/core/handlers/exception.py", line 47, in inner
    response = get_response(request)
  File "/home/martin/PycharmProjects/Torque/venv/lib/python3.8/site-packages/django/core/handlers/base.py", line 181, in _get_response
    response = wrapped_callback(request, *callback_args, **callback_kwargs)
  File "/home/martin/PycharmProjects/Torque/venv/lib/python3.8/site-packages/django/views/decorators/csrf.py", line 54, in wrapped_view
    return view_func(*args, **kwargs)
  File "/home/martin/PycharmProjects/Torque/models/views.py", line 490, in generate_custom_csv
    dataframe[i] = values
  File "/home/martin/PycharmProjects/Torque/venv/lib/python3.8/site-packages/pandas/core/frame.py", line 3163, in __setitem__
    self._set_item(key, value)
  File "/home/martin/PycharmProjects/Torque/venv/lib/python3.8/site-packages/pandas/core/frame.py", line 3242, in _set_item
    value = self._sanitize_column(key, value)
  File "/home/martin/PycharmProjects/Torque/venv/lib/python3.8/site-packages/pandas/core/frame.py", line 3899, in _sanitize_column
    value = sanitize_index(value, self.index)
  File "/home/martin/PycharmProjects/Torque/venv/lib/python3.8/site-packages/pandas/core/internals/construction.py", line 751, in sanitize_index
    raise ValueError(
ValueError: Length of values (1113) does not match length of index (1065)
ERROR:django.request:Internal Server Error: /generate_csv/
Traceback (most recent call last):
  File "/home/martin/PycharmProjects/Torque/venv/lib/python3.8/site-packages/django/core/handlers/exception.py", line 47, in inner
    response = get_response(request)
  File "/home/martin/PycharmProjects/Torque/venv/lib/python3.8/site-packages/django/core/handlers/base.py", line 181, in _get_response
    response = wrapped_callback(request, *callback_args, **callback_kwargs)
  File "/home/martin/PycharmProjects/Torque/venv/lib/python3.8/site-packages/django/views/decorators/csrf.py", line 54, in wrapped_view
    return view_func(*args, **kwargs)
  File "/home/martin/PycharmProjects/Torque/models/views.py", line 490, in generate_custom_csv
    dataframe[i] = values
  File "/home/martin/PycharmProjects/Torque/venv/lib/python3.8/site-packages/pandas/core/frame.py", line 3163, in __setitem__
    self._set_item(key, value)
  File "/home/martin/PycharmProjects/Torque/venv/lib/python3.8/site-packages/pandas/core/frame.py", line 3242, in _set_item
    value = self._sanitize_column(key, value)
  File "/home/martin/PycharmProjects/Torque/venv/lib/python3.8/site-packages/pandas/core/frame.py", line 3899, in _sanitize_column
    value = sanitize_index(value, self.index)
  File "/home/martin/PycharmProjects/Torque/venv/lib/python3.8/site-packages/pandas/core/internals/construction.py", line 751, in sanitize_index
    raise ValueError(
ValueError: Length of values (1113) does not match length of index (1065)
INFO:django.utils.autoreload:/home/martin/PycharmProjects/Torque/models/views.py changed, reloading.
INFO:django.utils.autoreload:/home/martin/PycharmProjects/Torque/models/views.py changed, reloading.
ERROR:django.request:Internal Server Error: /generate_csv/
Traceback (most recent call last):
  File "/home/martin/PycharmProjects/Torque/venv/lib/python3.8/site-packages/django/core/handlers/exception.py", line 47, in inner
    response = get_response(request)
  File "/home/martin/PycharmProjects/Torque/venv/lib/python3.8/site-packages/django/core/handlers/base.py", line 181, in _get_response
    response = wrapped_callback(request, *callback_args, **callback_kwargs)
  File "/home/martin/PycharmProjects/Torque/venv/lib/python3.8/site-packages/django/views/decorators/csrf.py", line 54, in wrapped_view
    return view_func(*args, **kwargs)
  File "/home/martin/PycharmProjects/Torque/models/views.py", line 487, in generate_custom_csv
    dataframe.append(values)
UnboundLocalError: local variable 'values' referenced before assignment
INFO:django.utils.autoreload:/home/martin/PycharmProjects/Torque/models/views.py changed, reloading.
ERROR:django.request:Internal Server Error: /generate_csv/
Traceback (most recent call last):
  File "/home/martin/PycharmProjects/Torque/venv/lib/python3.8/site-packages/django/core/handlers/exception.py", line 47, in inner
    response = get_response(request)
  File "/home/martin/PycharmProjects/Torque/venv/lib/python3.8/site-packages/django/core/handlers/base.py", line 181, in _get_response
    response = wrapped_callback(request, *callback_args, **callback_kwargs)
  File "/home/martin/PycharmProjects/Torque/venv/lib/python3.8/site-packages/django/views/decorators/csrf.py", line 54, in wrapped_view
    return view_func(*args, **kwargs)
  File "/home/martin/PycharmProjects/Torque/models/views.py", line 488, in generate_custom_csv
    dataframe.append(values)
  File "/home/martin/PycharmProjects/Torque/venv/lib/python3.8/site-packages/pandas/core/frame.py", line 7982, in append
    concat(
  File "/home/martin/PycharmProjects/Torque/venv/lib/python3.8/site-packages/pandas/core/reshape/concat.py", line 285, in concat
    op = _Concatenator(
  File "/home/martin/PycharmProjects/Torque/venv/lib/python3.8/site-packages/pandas/core/reshape/concat.py", line 370, in __init__
    raise TypeError(msg)
TypeError: cannot concatenate object of type '<class 'django.db.models.query.QuerySet'>'; only Series and DataFrame objs are valid
INFO:django.utils.autoreload:/home/martin/PycharmProjects/Torque/models/views.py changed, reloading.
INFO:django.utils.autoreload:/home/martin/PycharmProjects/Torque/models/views.py changed, reloading.
INFO:django.utils.autoreload:/home/martin/PycharmProjects/Torque/models/views.py changed, reloading.
ERROR:django.request:Internal Server Error: /generate_csv/
Traceback (most recent call last):
  File "/home/martin/PycharmProjects/Torque/venv/lib/python3.8/site-packages/django/core/handlers/exception.py", line 47, in inner
    response = get_response(request)
  File "/home/martin/PycharmProjects/Torque/venv/lib/python3.8/site-packages/django/core/handlers/base.py", line 181, in _get_response
    response = wrapped_callback(request, *callback_args, **callback_kwargs)
  File "/home/martin/PycharmProjects/Torque/venv/lib/python3.8/site-packages/django/views/decorators/csrf.py", line 54, in wrapped_view
    return view_func(*args, **kwargs)
  File "/home/martin/PycharmProjects/Torque/models/views.py", line 482, in generate_custom_csv
    dataframe = dataframe.columns.append(Sensor.objects.get(id=id_sensor).user_full_name)
  File "/home/martin/PycharmProjects/Torque/venv/lib/python3.8/site-packages/pandas/core/indexes/base.py", line 4351, in append
    raise TypeError("all inputs must be Index")
TypeError: all inputs must be Index
INFO:django.utils.autoreload:/home/martin/PycharmProjects/Torque/models/views.py changed, reloading.
INFO:django.utils.autoreload:/home/martin/PycharmProjects/Torque/models/views.py changed, reloading.
INFO:django.utils.autoreload:/home/martin/PycharmProjects/Torque/models/views.py changed, reloading.
INFO:django.utils.autoreload:/home/martin/PycharmProjects/Torque/models/views.py changed, reloading.
ERROR:django.request:Internal Server Error: /generate_csv/
Traceback (most recent call last):
  File "/home/martin/PycharmProjects/Torque/venv/lib/python3.8/site-packages/django/core/handlers/exception.py", line 47, in inner
    response = get_response(request)
  File "/home/martin/PycharmProjects/Torque/venv/lib/python3.8/site-packages/django/core/handlers/base.py", line 181, in _get_response
    response = wrapped_callback(request, *callback_args, **callback_kwargs)
  File "/home/martin/PycharmProjects/Torque/venv/lib/python3.8/site-packages/django/views/decorators/csrf.py", line 54, in wrapped_view
    return view_func(*args, **kwargs)
  File "/home/martin/PycharmProjects/Torque/models/views.py", line 499, in generate_custom_csv
    dataframe.columns = columns
  File "/home/martin/PycharmProjects/Torque/venv/lib/python3.8/site-packages/pandas/core/generic.py", line 5478, in __setattr__
    return object.__setattr__(self, name, value)
  File "pandas/_libs/properties.pyx", line 66, in pandas._libs.properties.AxisProperty.__set__
  File "/home/martin/PycharmProjects/Torque/venv/lib/python3.8/site-packages/pandas/core/generic.py", line 670, in _set_axis
    self._mgr.set_axis(axis, labels)
  File "/home/martin/PycharmProjects/Torque/venv/lib/python3.8/site-packages/pandas/core/internals/managers.py", line 220, in set_axis
    raise ValueError(
ValueError: Length mismatch: Expected axis has 1 elements, new values have 4 elements
INFO:django.utils.autoreload:/home/martin/PycharmProjects/Torque/models/views.py changed, reloading.
INFO:django.utils.autoreload:/home/martin/PycharmProjects/Torque/models/views.py changed, reloading.
INFO:django.utils.autoreload:/home/martin/PycharmProjects/Torque/models/views.py changed, reloading.
INFO:django.utils.autoreload:/home/martin/PycharmProjects/Torque/models/views.py changed, reloading.
ERROR:django.request:Internal Server Error: /generate_csv/
Traceback (most recent call last):
  File "/home/martin/PycharmProjects/Torque/venv/lib/python3.8/site-packages/django/core/handlers/exception.py", line 47, in inner
    response = get_response(request)
  File "/home/martin/PycharmProjects/Torque/venv/lib/python3.8/site-packages/django/core/handlers/base.py", line 181, in _get_response
    response = wrapped_callback(request, *callback_args, **callback_kwargs)
  File "/home/martin/PycharmProjects/Torque/venv/lib/python3.8/site-packages/django/views/decorators/csrf.py", line 54, in wrapped_view
    return view_func(*args, **kwargs)
  File "/home/martin/PycharmProjects/Torque/models/views.py", line 499, in generate_custom_csv
    dataframe = dataframe.rename(columns=columns)
  File "/home/martin/PycharmProjects/Torque/venv/lib/python3.8/site-packages/pandas/util/_decorators.py", line 312, in wrapper
    return func(*args, **kwargs)
  File "/home/martin/PycharmProjects/Torque/venv/lib/python3.8/site-packages/pandas/core/frame.py", line 4441, in rename
    return super().rename(
  File "/home/martin/PycharmProjects/Torque/venv/lib/python3.8/site-packages/pandas/core/generic.py", line 1057, in rename
    new_index = ax._transform_index(f, level)
  File "/home/martin/PycharmProjects/Torque/venv/lib/python3.8/site-packages/pandas/core/indexes/base.py", line 5138, in _transform_index
    items = [func(x) for x in self]
  File "/home/martin/PycharmProjects/Torque/venv/lib/python3.8/site-packages/pandas/core/indexes/base.py", line 5138, in <listcomp>
    items = [func(x) for x in self]
TypeError: 'list' object is not callable
INFO:django.utils.autoreload:/home/martin/PycharmProjects/Torque/models/views.py changed, reloading.
ERROR:django.request:Internal Server Error: /generate_csv/
Traceback (most recent call last):
  File "/home/martin/PycharmProjects/Torque/venv/lib/python3.8/site-packages/django/core/handlers/exception.py", line 47, in inner
    response = get_response(request)
  File "/home/martin/PycharmProjects/Torque/venv/lib/python3.8/site-packages/django/core/handlers/base.py", line 181, in _get_response
    response = wrapped_callback(request, *callback_args, **callback_kwargs)
  File "/home/martin/PycharmProjects/Torque/venv/lib/python3.8/site-packages/django/views/decorators/csrf.py", line 54, in wrapped_view
    return view_func(*args, **kwargs)
  File "/home/martin/PycharmProjects/Torque/models/views.py", line 499, in generate_custom_csv
    dataframe = dataframe.rename(columns=list(columns))
  File "/home/martin/PycharmProjects/Torque/venv/lib/python3.8/site-packages/pandas/util/_decorators.py", line 312, in wrapper
    return func(*args, **kwargs)
  File "/home/martin/PycharmProjects/Torque/venv/lib/python3.8/site-packages/pandas/core/frame.py", line 4441, in rename
    return super().rename(
  File "/home/martin/PycharmProjects/Torque/venv/lib/python3.8/site-packages/pandas/core/generic.py", line 1057, in rename
    new_index = ax._transform_index(f, level)
  File "/home/martin/PycharmProjects/Torque/venv/lib/python3.8/site-packages/pandas/core/indexes/base.py", line 5138, in _transform_index
    items = [func(x) for x in self]
  File "/home/martin/PycharmProjects/Torque/venv/lib/python3.8/site-packages/pandas/core/indexes/base.py", line 5138, in <listcomp>
    items = [func(x) for x in self]
TypeError: 'list' object is not callable
INFO:django.utils.autoreload:/home/martin/PycharmProjects/Torque/models/views.py changed, reloading.
INFO:django.utils.autoreload:/home/martin/PycharmProjects/Torque/models/views.py changed, reloading.
ERROR:django.request:Internal Server Error: /generate_csv/
Traceback (most recent call last):
  File "/home/martin/PycharmProjects/Torque/venv/lib/python3.8/site-packages/django/core/handlers/exception.py", line 47, in inner
    response = get_response(request)
  File "/home/martin/PycharmProjects/Torque/venv/lib/python3.8/site-packages/django/core/handlers/base.py", line 181, in _get_response
    response = wrapped_callback(request, *callback_args, **callback_kwargs)
  File "/home/martin/PycharmProjects/Torque/venv/lib/python3.8/site-packages/django/views/decorators/csrf.py", line 54, in wrapped_view
    return view_func(*args, **kwargs)
  File "/home/martin/PycharmProjects/Torque/models/views.py", line 499, in generate_custom_csv
    dataframe.rename(columns=columns)
  File "/home/martin/PycharmProjects/Torque/venv/lib/python3.8/site-packages/pandas/util/_decorators.py", line 312, in wrapper
    return func(*args, **kwargs)
  File "/home/martin/PycharmProjects/Torque/venv/lib/python3.8/site-packages/pandas/core/frame.py", line 4441, in rename
    return super().rename(
  File "/home/martin/PycharmProjects/Torque/venv/lib/python3.8/site-packages/pandas/core/generic.py", line 1057, in rename
    new_index = ax._transform_index(f, level)
  File "/home/martin/PycharmProjects/Torque/venv/lib/python3.8/site-packages/pandas/core/indexes/base.py", line 5138, in _transform_index
    items = [func(x) for x in self]
  File "/home/martin/PycharmProjects/Torque/venv/lib/python3.8/site-packages/pandas/core/indexes/base.py", line 5138, in <listcomp>
    items = [func(x) for x in self]
TypeError: 'list' object is not callable
ERROR:django.request:Internal Server Error: /generate_csv/
Traceback (most recent call last):
  File "/home/martin/PycharmProjects/Torque/venv/lib/python3.8/site-packages/django/core/handlers/exception.py", line 47, in inner
    response = get_response(request)
  File "/home/martin/PycharmProjects/Torque/venv/lib/python3.8/site-packages/django/core/handlers/base.py", line 181, in _get_response
    response = wrapped_callback(request, *callback_args, **callback_kwargs)
  File "/home/martin/PycharmProjects/Torque/venv/lib/python3.8/site-packages/django/views/decorators/csrf.py", line 54, in wrapped_view
    return view_func(*args, **kwargs)
  File "/home/martin/PycharmProjects/Torque/models/views.py", line 499, in generate_custom_csv
    dataframe.rename(columns=columns)
  File "/home/martin/PycharmProjects/Torque/venv/lib/python3.8/site-packages/pandas/util/_decorators.py", line 312, in wrapper
    return func(*args, **kwargs)
  File "/home/martin/PycharmProjects/Torque/venv/lib/python3.8/site-packages/pandas/core/frame.py", line 4441, in rename
    return super().rename(
  File "/home/martin/PycharmProjects/Torque/venv/lib/python3.8/site-packages/pandas/core/generic.py", line 1057, in rename
    new_index = ax._transform_index(f, level)
  File "/home/martin/PycharmProjects/Torque/venv/lib/python3.8/site-packages/pandas/core/indexes/base.py", line 5138, in _transform_index
    items = [func(x) for x in self]
  File "/home/martin/PycharmProjects/Torque/venv/lib/python3.8/site-packages/pandas/core/indexes/base.py", line 5138, in <listcomp>
    items = [func(x) for x in self]
TypeError: 'list' object is not callable
INFO:django.utils.autoreload:/home/martin/PycharmProjects/Torque/models/views.py changed, reloading.
INFO:django.utils.autoreload:/home/martin/PycharmProjects/Torque/models/views.py changed, reloading.
ERROR:django.request:Internal Server Error: /generate_csv/
Traceback (most recent call last):
  File "/home/martin/PycharmProjects/Torque/venv/lib/python3.8/site-packages/pandas/core/frame.py", line 3292, in _ensure_valid_index
    value = Series(value)
  File "/home/martin/PycharmProjects/Torque/venv/lib/python3.8/site-packages/pandas/core/series.py", line 268, in __init__
    if is_empty_data(data) and dtype is None:
  File "/home/martin/PycharmProjects/Torque/venv/lib/python3.8/site-packages/pandas/core/construction.py", line 628, in is_empty_data
    is_simple_empty = is_list_like_without_dtype and not data
  File "/home/martin/PycharmProjects/Torque/venv/lib/python3.8/site-packages/pandas/core/generic.py", line 1442, in __nonzero__
    raise ValueError(
ValueError: The truth value of a DataFrame is ambiguous. Use a.empty, a.bool(), a.item(), a.any() or a.all().

The above exception was the direct cause of the following exception:

Traceback (most recent call last):
  File "/home/martin/PycharmProjects/Torque/venv/lib/python3.8/site-packages/django/core/handlers/exception.py", line 47, in inner
    response = get_response(request)
  File "/home/martin/PycharmProjects/Torque/venv/lib/python3.8/site-packages/django/core/handlers/base.py", line 181, in _get_response
    response = wrapped_callback(request, *callback_args, **callback_kwargs)
  File "/home/martin/PycharmProjects/Torque/venv/lib/python3.8/site-packages/django/views/decorators/csrf.py", line 54, in wrapped_view
    return view_func(*args, **kwargs)
  File "/home/martin/PycharmProjects/Torque/models/views.py", line 488, in generate_custom_csv
    dataframe[i] = dataframe.append(list(values))
  File "/home/martin/PycharmProjects/Torque/venv/lib/python3.8/site-packages/pandas/core/frame.py", line 3163, in __setitem__
    self._set_item(key, value)
  File "/home/martin/PycharmProjects/Torque/venv/lib/python3.8/site-packages/pandas/core/frame.py", line 3241, in _set_item
    self._ensure_valid_index(value)
  File "/home/martin/PycharmProjects/Torque/venv/lib/python3.8/site-packages/pandas/core/frame.py", line 3294, in _ensure_valid_index
    raise ValueError(
ValueError: Cannot set a frame with no defined index and a value that cannot be converted to a Series
ERROR:django.request:Internal Server Error: /generate_csv/
Traceback (most recent call last):
  File "/home/martin/PycharmProjects/Torque/venv/lib/python3.8/site-packages/pandas/core/frame.py", line 3292, in _ensure_valid_index
    value = Series(value)
  File "/home/martin/PycharmProjects/Torque/venv/lib/python3.8/site-packages/pandas/core/series.py", line 268, in __init__
    if is_empty_data(data) and dtype is None:
  File "/home/martin/PycharmProjects/Torque/venv/lib/python3.8/site-packages/pandas/core/construction.py", line 628, in is_empty_data
    is_simple_empty = is_list_like_without_dtype and not data
  File "/home/martin/PycharmProjects/Torque/venv/lib/python3.8/site-packages/pandas/core/generic.py", line 1442, in __nonzero__
    raise ValueError(
ValueError: The truth value of a DataFrame is ambiguous. Use a.empty, a.bool(), a.item(), a.any() or a.all().

The above exception was the direct cause of the following exception:

Traceback (most recent call last):
  File "/home/martin/PycharmProjects/Torque/venv/lib/python3.8/site-packages/django/core/handlers/exception.py", line 47, in inner
    response = get_response(request)
  File "/home/martin/PycharmProjects/Torque/venv/lib/python3.8/site-packages/django/core/handlers/base.py", line 181, in _get_response
    response = wrapped_callback(request, *callback_args, **callback_kwargs)
  File "/home/martin/PycharmProjects/Torque/venv/lib/python3.8/site-packages/django/views/decorators/csrf.py", line 54, in wrapped_view
    return view_func(*args, **kwargs)
  File "/home/martin/PycharmProjects/Torque/models/views.py", line 488, in generate_custom_csv
    dataframe[i] = dataframe.append(list(values))
  File "/home/martin/PycharmProjects/Torque/venv/lib/python3.8/site-packages/pandas/core/frame.py", line 3163, in __setitem__
    self._set_item(key, value)
  File "/home/martin/PycharmProjects/Torque/venv/lib/python3.8/site-packages/pandas/core/frame.py", line 3241, in _set_item
    self._ensure_valid_index(value)
  File "/home/martin/PycharmProjects/Torque/venv/lib/python3.8/site-packages/pandas/core/frame.py", line 3294, in _ensure_valid_index
    raise ValueError(
ValueError: Cannot set a frame with no defined index and a value that cannot be converted to a Series
INFO:django.utils.autoreload:/home/martin/PycharmProjects/Torque/models/views.py changed, reloading.
INFO:django.utils.autoreload:/home/martin/PycharmProjects/Torque/models/views.py changed, reloading.
INFO:django.utils.autoreload:/home/martin/PycharmProjects/Torque/models/views.py changed, reloading.
INFO:django.utils.autoreload:/home/martin/PycharmProjects/Torque/models/views.py changed, reloading.
ERROR:django.request:Internal Server Error: /generate_csv/
Traceback (most recent call last):
  File "/home/martin/PycharmProjects/Torque/venv/lib/python3.8/site-packages/django/core/handlers/exception.py", line 47, in inner
    response = get_response(request)
  File "/home/martin/PycharmProjects/Torque/venv/lib/python3.8/site-packages/django/core/handlers/base.py", line 181, in _get_response
    response = wrapped_callback(request, *callback_args, **callback_kwargs)
  File "/home/martin/PycharmProjects/Torque/venv/lib/python3.8/site-packages/django/views/decorators/csrf.py", line 54, in wrapped_view
    return view_func(*args, **kwargs)
  File "/home/martin/PycharmProjects/Torque/models/views.py", line 488, in generate_custom_csv
    exec("df_val_%s = dataframe.append(list(%s))") % (i, values)
  File "<string>", line 1
    df_val_%s = dataframe.append(list(%s))
                                      ^
SyntaxError: invalid syntax
INFO:django.utils.autoreload:/home/martin/PycharmProjects/Torque/models/views.py changed, reloading.
ERROR:django.request:Internal Server Error: /generate_csv/
Traceback (most recent call last):
  File "/home/martin/PycharmProjects/Torque/venv/lib/python3.8/site-packages/django/core/handlers/exception.py", line 47, in inner
    response = get_response(request)
  File "/home/martin/PycharmProjects/Torque/venv/lib/python3.8/site-packages/django/core/handlers/base.py", line 181, in _get_response
    response = wrapped_callback(request, *callback_args, **callback_kwargs)
  File "/home/martin/PycharmProjects/Torque/venv/lib/python3.8/site-packages/django/views/decorators/csrf.py", line 54, in wrapped_view
    return view_func(*args, **kwargs)
  File "/home/martin/PycharmProjects/Torque/models/views.py", line 488, in generate_custom_csv
    exec("df_val_%s = list(%s)") % (i, values)
  File "<string>", line 1
    df_val_%s = list(%s))
                     ^
SyntaxError: invalid syntax
INFO:django.utils.autoreload:/home/martin/PycharmProjects/Torque/models/views.py changed, reloading.
ERROR:django.request:Internal Server Error: /generate_csv/
Traceback (most recent call last):
  File "/home/martin/PycharmProjects/Torque/venv/lib/python3.8/site-packages/django/core/handlers/exception.py", line 47, in inner
    response = get_response(request)
  File "/home/martin/PycharmProjects/Torque/venv/lib/python3.8/site-packages/django/core/handlers/base.py", line 181, in _get_response
    response = wrapped_callback(request, *callback_args, **callback_kwargs)
  File "/home/martin/PycharmProjects/Torque/venv/lib/python3.8/site-packages/django/views/decorators/csrf.py", line 54, in wrapped_view
    return view_func(*args, **kwargs)
  File "/home/martin/PycharmProjects/Torque/models/views.py", line 488, in generate_custom_csv
    exec("df_val_%s = %s") % (i, values)
  File "<string>", line 1
    df_val_%s = %s
                ^
SyntaxError: invalid syntax
INFO:django.utils.autoreload:/home/martin/PycharmProjects/Torque/models/views.py changed, reloading.
ERROR:django.request:Internal Server Error: /generate_csv/
Traceback (most recent call last):
  File "/home/martin/PycharmProjects/Torque/venv/lib/python3.8/site-packages/django/core/handlers/exception.py", line 47, in inner
    response = get_response(request)
  File "/home/martin/PycharmProjects/Torque/venv/lib/python3.8/site-packages/django/core/handlers/base.py", line 181, in _get_response
    response = wrapped_callback(request, *callback_args, **callback_kwargs)
  File "/home/martin/PycharmProjects/Torque/venv/lib/python3.8/site-packages/django/views/decorators/csrf.py", line 54, in wrapped_view
    return view_func(*args, **kwargs)
  File "/home/martin/PycharmProjects/Torque/models/views.py", line 488, in generate_custom_csv
    exec("df_val_%s") % i
  File "<string>", line 1, in <module>
NameError: name 'df_val_' is not defined
INFO:django.utils.autoreload:/home/martin/PycharmProjects/Torque/models/views.py changed, reloading.
ERROR:django.request:Internal Server Error: /generate_csv/
Traceback (most recent call last):
  File "/home/martin/PycharmProjects/Torque/venv/lib/python3.8/site-packages/django/core/handlers/exception.py", line 47, in inner
    response = get_response(request)
  File "/home/martin/PycharmProjects/Torque/venv/lib/python3.8/site-packages/django/core/handlers/base.py", line 181, in _get_response
    response = wrapped_callback(request, *callback_args, **callback_kwargs)
  File "/home/martin/PycharmProjects/Torque/venv/lib/python3.8/site-packages/django/views/decorators/csrf.py", line 54, in wrapped_view
    return view_func(*args, **kwargs)
  File "/home/martin/PycharmProjects/Torque/models/views.py", line 488, in generate_custom_csv
    exec("df_val_%s = none") % i
  File "<string>", line 1
SyntaxError: cannot assign to operator
INFO:django.utils.autoreload:/home/martin/PycharmProjects/Torque/models/views.py changed, reloading.
ERROR:django.request:Internal Server Error: /generate_csv/
Traceback (most recent call last):
  File "/home/martin/PycharmProjects/Torque/venv/lib/python3.8/site-packages/django/core/handlers/exception.py", line 47, in inner
    response = get_response(request)
  File "/home/martin/PycharmProjects/Torque/venv/lib/python3.8/site-packages/django/core/handlers/base.py", line 181, in _get_response
    response = wrapped_callback(request, *callback_args, **callback_kwargs)
  File "/home/martin/PycharmProjects/Torque/venv/lib/python3.8/site-packages/django/views/decorators/csrf.py", line 54, in wrapped_view
    return view_func(*args, **kwargs)
  File "/home/martin/PycharmProjects/Torque/models/views.py", line 488, in generate_custom_csv
    exec("df_val_%s = 1") % i
  File "<string>", line 1
SyntaxError: cannot assign to operator
INFO:django.utils.autoreload:/home/martin/PycharmProjects/Torque/models/views.py changed, reloading.
INFO:django.utils.autoreload:/home/martin/PycharmProjects/Torque/models/views.py changed, reloading.
ERROR:django.request:Internal Server Error: /generate_csv/
Traceback (most recent call last):
  File "/home/martin/PycharmProjects/Torque/venv/lib/python3.8/site-packages/django/core/handlers/exception.py", line 47, in inner
    response = get_response(request)
  File "/home/martin/PycharmProjects/Torque/venv/lib/python3.8/site-packages/django/core/handlers/base.py", line 181, in _get_response
    response = wrapped_callback(request, *callback_args, **callback_kwargs)
  File "/home/martin/PycharmProjects/Torque/venv/lib/python3.8/site-packages/django/views/decorators/csrf.py", line 54, in wrapped_view
    return view_func(*args, **kwargs)
  File "/home/martin/PycharmProjects/Torque/models/views.py", line 498, in generate_custom_csv
    dataframe = dataframe.columns.rename(columns)
  File "/home/martin/PycharmProjects/Torque/venv/lib/python3.8/site-packages/pandas/core/indexes/base.py", line 1441, in rename
    return self.set_names([name], inplace=inplace)
  File "/home/martin/PycharmProjects/Torque/venv/lib/python3.8/site-packages/pandas/core/indexes/base.py", line 1388, in set_names
    idx._set_names(names, level=level)
  File "/home/martin/PycharmProjects/Torque/venv/lib/python3.8/site-packages/pandas/core/indexes/base.py", line 1307, in _set_names
    validate_all_hashable(*values, error_name=f"{type(self).__name__}.name")
  File "/home/martin/PycharmProjects/Torque/venv/lib/python3.8/site-packages/pandas/core/dtypes/common.py", line 1764, in validate_all_hashable
    raise TypeError(f"{error_name} must be a hashable type")
TypeError: Index.name must be a hashable type
INFO:django.utils.autoreload:/home/martin/PycharmProjects/Torque/models/views.py changed, reloading.
ERROR:django.request:Internal Server Error: /generate_csv/
Traceback (most recent call last):
  File "/home/martin/PycharmProjects/Torque/venv/lib/python3.8/site-packages/django/core/handlers/exception.py", line 47, in inner
    response = get_response(request)
  File "/home/martin/PycharmProjects/Torque/venv/lib/python3.8/site-packages/django/core/handlers/base.py", line 181, in _get_response
    response = wrapped_callback(request, *callback_args, **callback_kwargs)
  File "/home/martin/PycharmProjects/Torque/venv/lib/python3.8/site-packages/django/views/decorators/csrf.py", line 54, in wrapped_view
    return view_func(*args, **kwargs)
  File "/home/martin/PycharmProjects/Torque/models/views.py", line 498, in generate_custom_csv
    dataframe = dataframe.columns.rename(columns,inplace=True)
  File "/home/martin/PycharmProjects/Torque/venv/lib/python3.8/site-packages/pandas/core/indexes/base.py", line 1441, in rename
    return self.set_names([name], inplace=inplace)
  File "/home/martin/PycharmProjects/Torque/venv/lib/python3.8/site-packages/pandas/core/indexes/base.py", line 1388, in set_names
    idx._set_names(names, level=level)
  File "/home/martin/PycharmProjects/Torque/venv/lib/python3.8/site-packages/pandas/core/indexes/base.py", line 1307, in _set_names
    validate_all_hashable(*values, error_name=f"{type(self).__name__}.name")
  File "/home/martin/PycharmProjects/Torque/venv/lib/python3.8/site-packages/pandas/core/dtypes/common.py", line 1764, in validate_all_hashable
    raise TypeError(f"{error_name} must be a hashable type")
TypeError: Index.name must be a hashable type
INFO:django.utils.autoreload:/home/martin/PycharmProjects/Torque/models/views.py changed, reloading.
ERROR:django.request:Internal Server Error: /generate_csv/
Traceback (most recent call last):
  File "/home/martin/PycharmProjects/Torque/venv/lib/python3.8/site-packages/pandas/core/indexes/base.py", line 3080, in get_loc
    return self._engine.get_loc(casted_key)
  File "pandas/_libs/index.pyx", line 70, in pandas._libs.index.IndexEngine.get_loc
  File "pandas/_libs/index.pyx", line 101, in pandas._libs.index.IndexEngine.get_loc
  File "pandas/_libs/hashtable_class_helper.pxi", line 4554, in pandas._libs.hashtable.PyObjectHashTable.get_item
  File "pandas/_libs/hashtable_class_helper.pxi", line 4562, in pandas._libs.hashtable.PyObjectHashTable.get_item
KeyError: 0

The above exception was the direct cause of the following exception:

Traceback (most recent call last):
  File "/home/martin/PycharmProjects/Torque/venv/lib/python3.8/site-packages/django/core/handlers/exception.py", line 47, in inner
    response = get_response(request)
  File "/home/martin/PycharmProjects/Torque/venv/lib/python3.8/site-packages/django/core/handlers/base.py", line 181, in _get_response
    response = wrapped_callback(request, *callback_args, **callback_kwargs)
  File "/home/martin/PycharmProjects/Torque/venv/lib/python3.8/site-packages/django/views/decorators/csrf.py", line 54, in wrapped_view
    return view_func(*args, **kwargs)
  File "/home/martin/PycharmProjects/Torque/models/views.py", line 489, in generate_custom_csv
    print(dataframe[i])
  File "/home/martin/PycharmProjects/Torque/venv/lib/python3.8/site-packages/pandas/core/frame.py", line 3024, in __getitem__
    indexer = self.columns.get_loc(key)
  File "/home/martin/PycharmProjects/Torque/venv/lib/python3.8/site-packages/pandas/core/indexes/base.py", line 3082, in get_loc
    raise KeyError(key) from err
KeyError: 0
INFO:django.utils.autoreload:/home/martin/PycharmProjects/Torque/models/views.py changed, reloading.
ERROR:django.request:Internal Server Error: /generate_csv/
Traceback (most recent call last):
  File "/home/martin/PycharmProjects/Torque/venv/lib/python3.8/site-packages/pandas/core/indexes/base.py", line 3080, in get_loc
    return self._engine.get_loc(casted_key)
  File "pandas/_libs/index.pyx", line 70, in pandas._libs.index.IndexEngine.get_loc
  File "pandas/_libs/index.pyx", line 101, in pandas._libs.index.IndexEngine.get_loc
  File "pandas/_libs/hashtable_class_helper.pxi", line 4554, in pandas._libs.hashtable.PyObjectHashTable.get_item
  File "pandas/_libs/hashtable_class_helper.pxi", line 4562, in pandas._libs.hashtable.PyObjectHashTable.get_item
KeyError: 1

The above exception was the direct cause of the following exception:

Traceback (most recent call last):
  File "/home/martin/PycharmProjects/Torque/venv/lib/python3.8/site-packages/django/core/handlers/exception.py", line 47, in inner
    response = get_response(request)
  File "/home/martin/PycharmProjects/Torque/venv/lib/python3.8/site-packages/django/core/handlers/base.py", line 181, in _get_response
    response = wrapped_callback(request, *callback_args, **callback_kwargs)
  File "/home/martin/PycharmProjects/Torque/venv/lib/python3.8/site-packages/django/views/decorators/csrf.py", line 54, in wrapped_view
    return view_func(*args, **kwargs)
  File "/home/martin/PycharmProjects/Torque/models/views.py", line 489, in generate_custom_csv
    print(dataframe[i])
  File "/home/martin/PycharmProjects/Torque/venv/lib/python3.8/site-packages/pandas/core/frame.py", line 3024, in __getitem__
    indexer = self.columns.get_loc(key)
  File "/home/martin/PycharmProjects/Torque/venv/lib/python3.8/site-packages/pandas/core/indexes/base.py", line 3082, in get_loc
    raise KeyError(key) from err
KeyError: 1
INFO:django.utils.autoreload:/home/martin/PycharmProjects/Torque/models/views.py changed, reloading.
INFO:django.utils.autoreload:/home/martin/PycharmProjects/Torque/models/views.py changed, reloading.
INFO:django.utils.autoreload:/home/martin/PycharmProjects/Torque/models/views.py changed, reloading.
INFO:django.utils.autoreload:/home/martin/PycharmProjects/Torque/models/views.py changed, reloading.
INFO:django.utils.autoreload:/home/martin/PycharmProjects/Torque/models/views.py changed, reloading.
ERROR:django.request:Internal Server Error: /generate_csv/
Traceback (most recent call last):
  File "/home/martin/PycharmProjects/Torque/venv/lib/python3.8/site-packages/django/core/handlers/exception.py", line 47, in inner
    response = get_response(request)
  File "/home/martin/PycharmProjects/Torque/venv/lib/python3.8/site-packages/django/core/handlers/base.py", line 181, in _get_response
    response = wrapped_callback(request, *callback_args, **callback_kwargs)
  File "/home/martin/PycharmProjects/Torque/venv/lib/python3.8/site-packages/django/views/decorators/csrf.py", line 54, in wrapped_view
    return view_func(*args, **kwargs)
  File "/home/martin/PycharmProjects/Torque/models/views.py", line 490, in generate_custom_csv
    dataframe = dataframe.append(list_values, columns=columns[i])
TypeError: append() got an unexpected keyword argument 'columns'
INFO:django.utils.autoreload:/home/martin/PycharmProjects/Torque/models/views.py changed, reloading.
ERROR:django.request:Internal Server Error: /generate_csv/
Traceback (most recent call last):
  File "/home/martin/PycharmProjects/Torque/venv/lib/python3.8/site-packages/django/core/handlers/exception.py", line 47, in inner
    response = get_response(request)
  File "/home/martin/PycharmProjects/Torque/venv/lib/python3.8/site-packages/django/core/handlers/base.py", line 181, in _get_response
    response = wrapped_callback(request, *callback_args, **callback_kwargs)
  File "/home/martin/PycharmProjects/Torque/venv/lib/python3.8/site-packages/django/views/decorators/csrf.py", line 54, in wrapped_view
    return view_func(*args, **kwargs)
  File "/home/martin/PycharmProjects/Torque/models/views.py", line 490, in generate_custom_csv
    dataframe = dataframe.append(list_values, column=columns[i])
TypeError: append() got an unexpected keyword argument 'column'
INFO:django.utils.autoreload:/home/martin/PycharmProjects/Torque/models/views.py changed, reloading.
ERROR:django.request:Internal Server Error: /generate_csv/
Traceback (most recent call last):
  File "/home/martin/PycharmProjects/Torque/venv/lib/python3.8/site-packages/django/core/handlers/exception.py", line 47, in inner
    response = get_response(request)
  File "/home/martin/PycharmProjects/Torque/venv/lib/python3.8/site-packages/django/core/handlers/base.py", line 181, in _get_response
    response = wrapped_callback(request, *callback_args, **callback_kwargs)
  File "/home/martin/PycharmProjects/Torque/venv/lib/python3.8/site-packages/django/views/decorators/csrf.py", line 54, in wrapped_view
    return view_func(*args, **kwargs)
  File "/home/martin/PycharmProjects/Torque/models/views.py", line 490, in generate_custom_csv
    dataframe = dataframe.append(list_values, columns=columns)
TypeError: append() got an unexpected keyword argument 'columns'
INFO:django.utils.autoreload:/home/martin/PycharmProjects/Torque/models/views.py changed, reloading.
INFO:django.utils.autoreload:/home/martin/PycharmProjects/Torque/models/views.py changed, reloading.
INFO:django.utils.autoreload:/home/martin/PycharmProjects/Torque/models/views.py changed, reloading.
INFO:django.utils.autoreload:/home/martin/PycharmProjects/Torque/models/views.py changed, reloading.
INFO:django.utils.autoreload:/home/martin/PycharmProjects/Torque/models/views.py changed, reloading.
INFO:django.utils.autoreload:/home/martin/PycharmProjects/Torque/models/views.py changed, reloading.
INFO:django.utils.autoreload:/home/martin/PycharmProjects/Torque/models/views.py changed, reloading.
INFO:django.utils.autoreload:/home/martin/PycharmProjects/Torque/models/views.py changed, reloading.
INFO:django.utils.autoreload:/home/martin/PycharmProjects/Torque/models/views.py changed, reloading.
INFO:django.utils.autoreload:/home/martin/PycharmProjects/Torque/models/views.py changed, reloading.
ERROR:django.request:Internal Server Error: /generate_csv/
Traceback (most recent call last):
  File "/home/martin/PycharmProjects/Torque/venv/lib/python3.8/site-packages/django/core/handlers/exception.py", line 47, in inner
    response = get_response(request)
  File "/home/martin/PycharmProjects/Torque/venv/lib/python3.8/site-packages/django/core/handlers/base.py", line 181, in _get_response
    response = wrapped_callback(request, *callback_args, **callback_kwargs)
  File "/home/martin/PycharmProjects/Torque/venv/lib/python3.8/site-packages/django/views/decorators/csrf.py", line 54, in wrapped_view
    return view_func(*args, **kwargs)
  File "/home/martin/PycharmProjects/Torque/models/views.py", line 490, in generate_custom_csv
    dictionary[columns[i]] = list_values
NameError: name 'i' is not defined
INFO:django.utils.autoreload:/home/martin/PycharmProjects/Torque/models/views.py changed, reloading.
INFO:django.utils.autoreload:/home/martin/PycharmProjects/Torque/models/views.py changed, reloading.
INFO:django.utils.autoreload:/home/martin/PycharmProjects/Torque/models/views.py changed, reloading.
INFO:django.utils.autoreload:/home/martin/PycharmProjects/Torque/models/views.py changed, reloading.
INFO:django.utils.autoreload:/home/martin/PycharmProjects/Torque/models/views.py changed, reloading.
INFO:django.utils.autoreload:/home/martin/PycharmProjects/Torque/models/views.py changed, reloading.
INFO:django.utils.autoreload:/home/martin/PycharmProjects/Torque/models/views.py changed, reloading.
INFO:django.utils.autoreload:/home/martin/PycharmProjects/Torque/models/views.py changed, reloading.
INFO:django.utils.autoreload:/home/martin/PycharmProjects/Torque/models/views.py changed, reloading.
INFO:django.utils.autoreload:/home/martin/PycharmProjects/Torque/models/views.py changed, reloading.
INFO:django.utils.autoreload:/home/martin/PycharmProjects/Torque/models/views.py changed, reloading.
INFO:django.utils.autoreload:/home/martin/PycharmProjects/Torque/models/views.py changed, reloading.
INFO:django.utils.autoreload:/home/martin/PycharmProjects/Torque/models/views.py changed, reloading.
INFO:django.utils.autoreload:/home/martin/PycharmProjects/Torque/models/views.py changed, reloading.
INFO:django.utils.autoreload:/home/martin/PycharmProjects/Torque/models/views.py changed, reloading.
ERROR:django.request:Internal Server Error: /generate_csv/
Traceback (most recent call last):
  File "/home/martin/PycharmProjects/Torque/venv/lib/python3.8/site-packages/django/core/handlers/exception.py", line 47, in inner
    response = get_response(request)
  File "/home/martin/PycharmProjects/Torque/venv/lib/python3.8/site-packages/django/core/handlers/base.py", line 181, in _get_response
    response = wrapped_callback(request, *callback_args, **callback_kwargs)
  File "/home/martin/PycharmProjects/Torque/venv/lib/python3.8/site-packages/django/views/decorators/csrf.py", line 54, in wrapped_view
    return view_func(*args, **kwargs)
  File "/home/martin/PycharmProjects/Torque/models/views.py", line 511, in generate_custom_csv
    dict_df.to_csv(path_or_buf='./data/' + filename+'.csv')
  File "/home/martin/PycharmProjects/Torque/venv/lib/python3.8/site-packages/pandas/core/generic.py", line 3387, in to_csv
    return DataFrameRenderer(formatter).to_csv(
  File "/home/martin/PycharmProjects/Torque/venv/lib/python3.8/site-packages/pandas/io/formats/format.py", line 1083, in to_csv
    csv_formatter.save()
  File "/home/martin/PycharmProjects/Torque/venv/lib/python3.8/site-packages/pandas/io/formats/csvs.py", line 228, in save
    with get_handle(
  File "/home/martin/PycharmProjects/Torque/venv/lib/python3.8/site-packages/pandas/io/common.py", line 642, in get_handle
    handle = open(
FileNotFoundError: [Errno 2] No such file or directory: './data/session300.csv'
INFO:django.utils.autoreload:/home/martin/PycharmProjects/Torque/models/views.py changed, reloading.
ERROR:django.request:Internal Server Error: /generate_csv/
Traceback (most recent call last):
  File "/home/martin/PycharmProjects/Torque/venv/lib/python3.8/site-packages/django/core/handlers/exception.py", line 47, in inner
    response = get_response(request)
  File "/home/martin/PycharmProjects/Torque/venv/lib/python3.8/site-packages/django/core/handlers/base.py", line 181, in _get_response
    response = wrapped_callback(request, *callback_args, **callback_kwargs)
  File "/home/martin/PycharmProjects/Torque/venv/lib/python3.8/site-packages/django/views/decorators/csrf.py", line 54, in wrapped_view
    return view_func(*args, **kwargs)
  File "/home/martin/PycharmProjects/Torque/models/views.py", line 511, in generate_custom_csv
    dict_df.to_csv(path_or_buf='/data/' + filename+'.csv')
  File "/home/martin/PycharmProjects/Torque/venv/lib/python3.8/site-packages/pandas/core/generic.py", line 3387, in to_csv
    return DataFrameRenderer(formatter).to_csv(
  File "/home/martin/PycharmProjects/Torque/venv/lib/python3.8/site-packages/pandas/io/formats/format.py", line 1083, in to_csv
    csv_formatter.save()
  File "/home/martin/PycharmProjects/Torque/venv/lib/python3.8/site-packages/pandas/io/formats/csvs.py", line 228, in save
    with get_handle(
  File "/home/martin/PycharmProjects/Torque/venv/lib/python3.8/site-packages/pandas/io/common.py", line 642, in get_handle
    handle = open(
FileNotFoundError: [Errno 2] No such file or directory: '/data/session300.csv'
INFO:django.utils.autoreload:/home/martin/PycharmProjects/Torque/models/views.py changed, reloading.
INFO:django.utils.autoreload:/home/martin/PycharmProjects/Torque/models/views.py changed, reloading.
INFO:django.utils.autoreload:/home/martin/PycharmProjects/Torque/models/views.py changed, reloading.
INFO:django.utils.autoreload:/home/martin/PycharmProjects/Torque/models/views.py changed, reloading.
INFO:django.utils.autoreload:/home/martin/PycharmProjects/Torque/models/views.py changed, reloading.
ERROR:django.request:Internal Server Error: /generate_csv/
Traceback (most recent call last):
  File "/home/martin/PycharmProjects/Torque/venv/lib/python3.8/site-packages/django/core/handlers/exception.py", line 47, in inner
    response = get_response(request)
  File "/home/martin/PycharmProjects/Torque/venv/lib/python3.8/site-packages/django/core/handlers/base.py", line 181, in _get_response
    response = wrapped_callback(request, *callback_args, **callback_kwargs)
  File "/home/martin/PycharmProjects/Torque/venv/lib/python3.8/site-packages/django/views/decorators/csrf.py", line 54, in wrapped_view
    return view_func(*args, **kwargs)
  File "/home/martin/PycharmProjects/Torque/models/views.py", line 473, in generate_custom_csv
    data = json.loads(request.GET.get())
TypeError: get() missing 1 required positional argument: 'key'
INFO:django.utils.autoreload:/home/martin/PycharmProjects/Torque/models/views.py changed, reloading.
ERROR:django.request:Internal Server Error: /generate_csv/
Traceback (most recent call last):
  File "/home/martin/PycharmProjects/Torque/venv/lib/python3.8/site-packages/django/core/handlers/exception.py", line 47, in inner
    response = get_response(request)
  File "/home/martin/PycharmProjects/Torque/venv/lib/python3.8/site-packages/django/core/handlers/base.py", line 181, in _get_response
    response = wrapped_callback(request, *callback_args, **callback_kwargs)
  File "/home/martin/PycharmProjects/Torque/venv/lib/python3.8/site-packages/django/views/decorators/csrf.py", line 54, in wrapped_view
    return view_func(*args, **kwargs)
  File "/home/martin/PycharmProjects/Torque/models/views.py", line 473, in generate_custom_csv
    data = json.loads(request.GET)
  File "/usr/lib/python3.8/json/__init__.py", line 341, in loads
    raise TypeError(f'the JSON object must be str, bytes or bytearray, '
TypeError: the JSON object must be str, bytes or bytearray, not QueryDict
INFO:django.utils.autoreload:/home/martin/PycharmProjects/Torque/models/views.py changed, reloading.
INFO:django.utils.autoreload:/home/martin/PycharmProjects/Torque/models/views.py changed, reloading.
ERROR:django.request:Internal Server Error: /generate_csv/
Traceback (most recent call last):
  File "/home/martin/PycharmProjects/Torque/venv/lib/python3.8/site-packages/django/core/handlers/exception.py", line 47, in inner
    response = get_response(request)
  File "/home/martin/PycharmProjects/Torque/venv/lib/python3.8/site-packages/django/core/handlers/base.py", line 181, in _get_response
    response = wrapped_callback(request, *callback_args, **callback_kwargs)
  File "/home/martin/PycharmProjects/Torque/venv/lib/python3.8/site-packages/django/views/decorators/csrf.py", line 54, in wrapped_view
    return view_func(*args, **kwargs)
  File "/home/martin/PycharmProjects/Torque/models/views.py", line 473, in generate_custom_csv
    data = json.loads(request.GET.get('idSensors'))
  File "/usr/lib/python3.8/json/__init__.py", line 341, in loads
    raise TypeError(f'the JSON object must be str, bytes or bytearray, '
TypeError: the JSON object must be str, bytes or bytearray, not NoneType
ERROR:django.request:Internal Server Error: /generate_csv/
Traceback (most recent call last):
  File "/home/martin/PycharmProjects/Torque/venv/lib/python3.8/site-packages/django/core/handlers/exception.py", line 47, in inner
    response = get_response(request)
  File "/home/martin/PycharmProjects/Torque/venv/lib/python3.8/site-packages/django/core/handlers/base.py", line 181, in _get_response
    response = wrapped_callback(request, *callback_args, **callback_kwargs)
  File "/home/martin/PycharmProjects/Torque/venv/lib/python3.8/site-packages/django/views/decorators/csrf.py", line 54, in wrapped_view
    return view_func(*args, **kwargs)
  File "/home/martin/PycharmProjects/Torque/models/views.py", line 473, in generate_custom_csv
    data = json.loads(request.GET.get('idSensors'))
  File "/usr/lib/python3.8/json/__init__.py", line 341, in loads
    raise TypeError(f'the JSON object must be str, bytes or bytearray, '
TypeError: the JSON object must be str, bytes or bytearray, not NoneType
INFO:django.utils.autoreload:/home/martin/PycharmProjects/Torque/models/views.py changed, reloading.
ERROR:django.request:Internal Server Error: /generate_csv/
Traceback (most recent call last):
  File "/home/martin/PycharmProjects/Torque/venv/lib/python3.8/site-packages/django/core/handlers/exception.py", line 47, in inner
    response = get_response(request)
  File "/home/martin/PycharmProjects/Torque/venv/lib/python3.8/site-packages/django/core/handlers/base.py", line 181, in _get_response
    response = wrapped_callback(request, *callback_args, **callback_kwargs)
  File "/home/martin/PycharmProjects/Torque/venv/lib/python3.8/site-packages/django/views/decorators/csrf.py", line 54, in wrapped_view
    return view_func(*args, **kwargs)
  File "/home/martin/PycharmProjects/Torque/models/views.py", line 473, in generate_custom_csv
    data = json.loads(request.GET.get('idSensors'))
  File "/usr/lib/python3.8/json/__init__.py", line 341, in loads
    raise TypeError(f'the JSON object must be str, bytes or bytearray, '
TypeError: the JSON object must be str, bytes or bytearray, not NoneType
INFO:django.utils.autoreload:/home/martin/PycharmProjects/Torque/models/views.py changed, reloading.
ERROR:django.request:Internal Server Error: /generate_csv/
Traceback (most recent call last):
  File "/home/martin/PycharmProjects/Torque/venv/lib/python3.8/site-packages/django/core/handlers/exception.py", line 47, in inner
    response = get_response(request)
  File "/home/martin/PycharmProjects/Torque/venv/lib/python3.8/site-packages/django/core/handlers/base.py", line 181, in _get_response
    response = wrapped_callback(request, *callback_args, **callback_kwargs)
  File "/home/martin/PycharmProjects/Torque/venv/lib/python3.8/site-packages/django/views/decorators/csrf.py", line 54, in wrapped_view
    return view_func(*args, **kwargs)
  File "/home/martin/PycharmProjects/Torque/models/views.py", line 479, in generate_custom_csv
    log = Log.objects.get(id=id_session)
  File "/home/martin/PycharmProjects/Torque/venv/lib/python3.8/site-packages/django/db/models/manager.py", line 85, in manager_method
    return getattr(self.get_queryset(), name)(*args, **kwargs)
  File "/home/martin/PycharmProjects/Torque/venv/lib/python3.8/site-packages/django/db/models/query.py", line 429, in get
    raise self.model.DoesNotExist(
models.models.Log.DoesNotExist: Log matching query does not exist.
INFO:django.utils.autoreload:/home/martin/PycharmProjects/Torque/models/views.py changed, reloading.
ERROR:django.request:Internal Server Error: /generate_csv/
Traceback (most recent call last):
  File "/home/martin/PycharmProjects/Torque/venv/lib/python3.8/site-packages/django/core/handlers/exception.py", line 47, in inner
    response = get_response(request)
  File "/home/martin/PycharmProjects/Torque/venv/lib/python3.8/site-packages/django/core/handlers/base.py", line 181, in _get_response
    response = wrapped_callback(request, *callback_args, **callback_kwargs)
  File "/home/martin/PycharmProjects/Torque/venv/lib/python3.8/site-packages/django/views/decorators/csrf.py", line 54, in wrapped_view
    return view_func(*args, **kwargs)
  File "/home/martin/PycharmProjects/Torque/models/views.py", line 473, in generate_custom_csv
    data = json.loads(request.GET.get('idSensors'))
  File "/usr/lib/python3.8/json/__init__.py", line 341, in loads
    raise TypeError(f'the JSON object must be str, bytes or bytearray, '
TypeError: the JSON object must be str, bytes or bytearray, not NoneType
INFO:django.utils.autoreload:/home/martin/PycharmProjects/Torque/models/views.py changed, reloading.
ERROR:django.request:Internal Server Error: /generate_csv/
Traceback (most recent call last):
  File "/home/martin/PycharmProjects/Torque/venv/lib/python3.8/site-packages/django/core/handlers/exception.py", line 47, in inner
    response = get_response(request)
  File "/home/martin/PycharmProjects/Torque/venv/lib/python3.8/site-packages/django/core/handlers/base.py", line 181, in _get_response
    response = wrapped_callback(request, *callback_args, **callback_kwargs)
  File "/home/martin/PycharmProjects/Torque/venv/lib/python3.8/site-packages/django/views/decorators/csrf.py", line 54, in wrapped_view
    return view_func(*args, **kwargs)
  File "/home/martin/PycharmProjects/Torque/models/views.py", line 473, in generate_custom_csv
    data = json.loads(request.GET.get('idSenssion'))
  File "/usr/lib/python3.8/json/__init__.py", line 341, in loads
    raise TypeError(f'the JSON object must be str, bytes or bytearray, '
TypeError: the JSON object must be str, bytes or bytearray, not NoneType
INFO:django.utils.autoreload:/home/martin/PycharmProjects/Torque/models/views.py changed, reloading.
ERROR:django.request:Internal Server Error: /generate_csv/
Traceback (most recent call last):
  File "/home/martin/PycharmProjects/Torque/venv/lib/python3.8/site-packages/django/core/handlers/exception.py", line 47, in inner
    response = get_response(request)
  File "/home/martin/PycharmProjects/Torque/venv/lib/python3.8/site-packages/django/core/handlers/base.py", line 181, in _get_response
    response = wrapped_callback(request, *callback_args, **callback_kwargs)
  File "/home/martin/PycharmProjects/Torque/venv/lib/python3.8/site-packages/django/views/decorators/csrf.py", line 54, in wrapped_view
    return view_func(*args, **kwargs)
  File "/home/martin/PycharmProjects/Torque/models/views.py", line 473, in generate_custom_csv
    data = json.loads(request.body)
  File "/usr/lib/python3.8/json/__init__.py", line 357, in loads
    return _default_decoder.decode(s)
  File "/usr/lib/python3.8/json/decoder.py", line 337, in decode
    obj, end = self.raw_decode(s, idx=_w(s, 0).end())
  File "/usr/lib/python3.8/json/decoder.py", line 355, in raw_decode
    raise JSONDecodeError("Expecting value", s, err.value) from None
json.decoder.JSONDecodeError: Expecting value: line 1 column 1 (char 0)
INFO:django.utils.autoreload:/home/martin/PycharmProjects/Torque/models/views.py changed, reloading.
ERROR:django.request:Internal Server Error: /generate_csv/
Traceback (most recent call last):
  File "/home/martin/PycharmProjects/Torque/venv/lib/python3.8/site-packages/django/core/handlers/exception.py", line 47, in inner
    response = get_response(request)
  File "/home/martin/PycharmProjects/Torque/venv/lib/python3.8/site-packages/django/core/handlers/base.py", line 181, in _get_response
    response = wrapped_callback(request, *callback_args, **callback_kwargs)
  File "/home/martin/PycharmProjects/Torque/venv/lib/python3.8/site-packages/django/views/decorators/csrf.py", line 54, in wrapped_view
    return view_func(*args, **kwargs)
  File "/home/martin/PycharmProjects/Torque/models/views.py", line 473, in generate_custom_csv
    data = json.loads(request.body)
  File "/usr/lib/python3.8/json/__init__.py", line 357, in loads
    return _default_decoder.decode(s)
  File "/usr/lib/python3.8/json/decoder.py", line 337, in decode
    obj, end = self.raw_decode(s, idx=_w(s, 0).end())
  File "/usr/lib/python3.8/json/decoder.py", line 355, in raw_decode
    raise JSONDecodeError("Expecting value", s, err.value) from None
json.decoder.JSONDecodeError: Expecting value: line 1 column 1 (char 0)
ERROR:django.request:Internal Server Error: /generate_csv/
Traceback (most recent call last):
  File "/home/martin/PycharmProjects/Torque/venv/lib/python3.8/site-packages/django/core/handlers/exception.py", line 47, in inner
    response = get_response(request)
  File "/home/martin/PycharmProjects/Torque/venv/lib/python3.8/site-packages/django/core/handlers/base.py", line 181, in _get_response
    response = wrapped_callback(request, *callback_args, **callback_kwargs)
  File "/home/martin/PycharmProjects/Torque/venv/lib/python3.8/site-packages/django/views/decorators/csrf.py", line 54, in wrapped_view
    return view_func(*args, **kwargs)
  File "/home/martin/PycharmProjects/Torque/models/views.py", line 473, in generate_custom_csv
    data = json.loads(request.body)
  File "/usr/lib/python3.8/json/__init__.py", line 357, in loads
    return _default_decoder.decode(s)
  File "/usr/lib/python3.8/json/decoder.py", line 337, in decode
    obj, end = self.raw_decode(s, idx=_w(s, 0).end())
  File "/usr/lib/python3.8/json/decoder.py", line 355, in raw_decode
    raise JSONDecodeError("Expecting value", s, err.value) from None
json.decoder.JSONDecodeError: Expecting value: line 1 column 1 (char 0)
ERROR:django.request:Internal Server Error: /generate_csv/
Traceback (most recent call last):
  File "/home/martin/PycharmProjects/Torque/venv/lib/python3.8/site-packages/django/core/handlers/exception.py", line 47, in inner
    response = get_response(request)
  File "/home/martin/PycharmProjects/Torque/venv/lib/python3.8/site-packages/django/core/handlers/base.py", line 181, in _get_response
    response = wrapped_callback(request, *callback_args, **callback_kwargs)
  File "/home/martin/PycharmProjects/Torque/venv/lib/python3.8/site-packages/django/views/decorators/csrf.py", line 54, in wrapped_view
    return view_func(*args, **kwargs)
  File "/home/martin/PycharmProjects/Torque/models/views.py", line 475, in generate_custom_csv
    id_session = data('idSenssion')
TypeError: 'dict' object is not callable
INFO:django.utils.autoreload:/home/martin/PycharmProjects/Torque/models/views.py changed, reloading.
ERROR:django.request:Internal Server Error: /generate_csv/
Traceback (most recent call last):
  File "/home/martin/PycharmProjects/Torque/venv/lib/python3.8/site-packages/django/core/handlers/exception.py", line 47, in inner
    response = get_response(request)
  File "/home/martin/PycharmProjects/Torque/venv/lib/python3.8/site-packages/django/core/handlers/base.py", line 181, in _get_response
    response = wrapped_callback(request, *callback_args, **callback_kwargs)
  File "/home/martin/PycharmProjects/Torque/venv/lib/python3.8/site-packages/django/views/decorators/csrf.py", line 54, in wrapped_view
    return view_func(*args, **kwargs)
  File "/home/martin/PycharmProjects/Torque/models/views.py", line 475, in generate_custom_csv
    id_session = data['idSenssion']
KeyError: 'idSenssion'
INFO:django.utils.autoreload:/home/martin/PycharmProjects/Torque/models/views.py changed, reloading.
INFO:django.utils.autoreload:/home/martin/PycharmProjects/Torque/models/views.py changed, reloading.
INFO:django.utils.autoreload:/home/martin/PycharmProjects/Torque/models/views.py changed, reloading.
INFO:django.utils.autoreload:/home/martin/PycharmProjects/Torque/models/views.py changed, reloading.
INFO:django.utils.autoreload:/home/martin/PycharmProjects/Torque/models/views.py changed, reloading.
INFO:django.utils.autoreload:/home/martin/PycharmProjects/Torque/models/views.py changed, reloading.
INFO:django.utils.autoreload:/home/martin/PycharmProjects/Torque/models/views.py changed, reloading.
INFO:django.utils.autoreload:/home/martin/PycharmProjects/Torque/models/views.py changed, reloading.
INFO:django.utils.autoreload:/home/martin/PycharmProjects/Torque/models/views.py changed, reloading.
INFO:django.utils.autoreload:/home/martin/PycharmProjects/Torque/models/views.py changed, reloading.
INFO:django.utils.autoreload:/home/martin/PycharmProjects/Torque/models/views.py changed, reloading.
INFO:django.utils.autoreload:/home/martin/PycharmProjects/Torque/models/views.py changed, reloading.
INFO:django.utils.autoreload:/home/martin/PycharmProjects/Torque/models/views.py changed, reloading.
INFO:django.utils.autoreload:/home/martin/PycharmProjects/Torque/models/views.py changed, reloading.
INFO:django.utils.autoreload:/home/martin/PycharmProjects/Torque/models/views.py changed, reloading.
INFO:django.utils.autoreload:/home/martin/PycharmProjects/Torque/models/views.py changed, reloading.
INFO:django.utils.autoreload:/home/martin/PycharmProjects/Torque/models/views.py changed, reloading.
INFO:django.utils.autoreload:/home/martin/PycharmProjects/Torque/models/views.py changed, reloading.
INFO:django.utils.autoreload:/home/martin/PycharmProjects/Torque/models/views.py changed, reloading.
INFO:django.utils.autoreload:/home/martin/PycharmProjects/Torque/models/views.py changed, reloading.
INFO:django.utils.autoreload:/home/martin/PycharmProjects/Torque/models/views.py changed, reloading.
INFO:django.utils.autoreload:/home/martin/PycharmProjects/Torque/models/views.py changed, reloading.
INFO:django.utils.autoreload:/home/martin/PycharmProjects/Torque/models/views.py changed, reloading.
INFO:django.utils.autoreload:/home/martin/PycharmProjects/Torque/models/views.py changed, reloading.
INFO:django.utils.autoreload:/home/martin/PycharmProjects/Torque/models/views.py changed, reloading.
INFO:django.utils.autoreload:/home/martin/PycharmProjects/Torque/models/views.py changed, reloading.
INFO:django.utils.autoreload:/home/martin/PycharmProjects/Torque/models/views.py changed, reloading.
INFO:django.utils.autoreload:/home/martin/PycharmProjects/Torque/models/views.py changed, reloading.
INFO:django.utils.autoreload:/home/martin/PycharmProjects/Torque/models/views.py changed, reloading.
INFO:django.utils.autoreload:/home/martin/PycharmProjects/Torque/models/views.py changed, reloading.
INFO:django.utils.autoreload:/home/martin/PycharmProjects/Torque/models/views.py changed, reloading.
ERROR:django.request:Internal Server Error: /generate_csv/
Traceback (most recent call last):
  File "/home/martin/PycharmProjects/Torque/venv/lib/python3.8/site-packages/django/core/handlers/exception.py", line 47, in inner
    response = get_response(request)
  File "/home/martin/PycharmProjects/Torque/venv/lib/python3.8/site-packages/django/core/handlers/base.py", line 188, in _get_response
    self.check_response(response, callback)
  File "/home/martin/PycharmProjects/Torque/venv/lib/python3.8/site-packages/django/core/handlers/base.py", line 309, in check_response
    raise ValueError(
ValueError: The view models.views.generate_custom_csv didn't return an HttpResponse object. It returned None instead.
ERROR:django.request:Internal Server Error: /generate_csv/
Traceback (most recent call last):
  File "/home/martin/PycharmProjects/Torque/venv/lib/python3.8/site-packages/django/core/handlers/exception.py", line 47, in inner
    response = get_response(request)
  File "/home/martin/PycharmProjects/Torque/venv/lib/python3.8/site-packages/django/core/handlers/base.py", line 188, in _get_response
    self.check_response(response, callback)
  File "/home/martin/PycharmProjects/Torque/venv/lib/python3.8/site-packages/django/core/handlers/base.py", line 309, in check_response
    raise ValueError(
ValueError: The view models.views.generate_custom_csv didn't return an HttpResponse object. It returned None instead.
INFO:django.utils.autoreload:/home/martin/PycharmProjects/Torque/models/views.py changed, reloading.
INFO:django.utils.autoreload:/home/martin/PycharmProjects/Torque/models/views.py changed, reloading.
INFO:django.utils.autoreload:/home/martin/PycharmProjects/Torque/models/views.py changed, reloading.
INFO:django.utils.autoreload:/home/martin/PycharmProjects/Torque/models/views.py changed, reloading.
INFO:django.utils.autoreload:/home/martin/PycharmProjects/Torque/models/views.py changed, reloading.
INFO:django.utils.autoreload:/home/martin/PycharmProjects/Torque/models/views.py changed, reloading.
INFO:django.utils.autoreload:/home/martin/PycharmProjects/Torque/models/views.py changed, reloading.
INFO:django.utils.autoreload:/home/martin/PycharmProjects/Torque/models/views.py changed, reloading.
INFO:django.utils.autoreload:/home/martin/PycharmProjects/Torque/models/views.py changed, reloading.
INFO:django.utils.autoreload:/home/martin/PycharmProjects/Torque/models/views.py changed, reloading.
INFO:django.utils.autoreload:/home/martin/PycharmProjects/Torque/models/views.py changed, reloading.
INFO:django.utils.autoreload:/home/martin/PycharmProjects/Torque/models/views.py changed, reloading.
INFO:django.utils.autoreload:/home/martin/PycharmProjects/Torque/models/views.py changed, reloading.
INFO:django.utils.autoreload:/home/martin/PycharmProjects/Torque/models/views.py changed, reloading.
INFO:django.utils.autoreload:/home/martin/PycharmProjects/Torque/models/views.py changed, reloading.
INFO:django.utils.autoreload:/home/martin/PycharmProjects/Torque/models/views.py changed, reloading.
INFO:django.utils.autoreload:/home/martin/PycharmProjects/Torque/models/views.py changed, reloading.
INFO:django.utils.autoreload:/home/martin/PycharmProjects/Torque/models/views.py changed, reloading.
INFO:django.utils.autoreload:/home/martin/PycharmProjects/Torque/models/views.py changed, reloading.
INFO:django.utils.autoreload:/home/martin/PycharmProjects/Torque/models/views.py changed, reloading.
INFO:django.utils.autoreload:/home/martin/PycharmProjects/Torque/models/views.py changed, reloading.
INFO:django.utils.autoreload:/home/martin/PycharmProjects/Torque/models/views.py changed, reloading.
INFO:django.utils.autoreload:/home/martin/PycharmProjects/Torque/models/views.py changed, reloading.
INFO:django.utils.autoreload:/home/martin/PycharmProjects/Torque/models/views.py changed, reloading.
ERROR:django.request:Internal Server Error: /generate_csv/
Traceback (most recent call last):
  File "/home/martin/PycharmProjects/Torque/venv/lib/python3.8/site-packages/django/core/handlers/exception.py", line 47, in inner
    response = get_response(request)
  File "/home/martin/PycharmProjects/Torque/venv/lib/python3.8/site-packages/django/core/handlers/base.py", line 181, in _get_response
    response = wrapped_callback(request, *callback_args, **callback_kwargs)
  File "/home/martin/PycharmProjects/Torque/venv/lib/python3.8/site-packages/django/views/decorators/csrf.py", line 54, in wrapped_view
    return view_func(*args, **kwargs)
  File "/home/martin/PycharmProjects/Torque/models/views.py", line 486, in generate_custom_csv
    columns.append(
AttributeError: 'NoneType' object has no attribute 'replace'
INFO:django.utils.autoreload:/home/martin/PycharmProjects/Torque/models/views.py changed, reloading.
INFO:django.utils.autoreload:/home/martin/PycharmProjects/Torque/models/views.py changed, reloading.
INFO:django.utils.autoreload:/home/martin/PycharmProjects/Torque/models/views.py changed, reloading.
INFO:django.utils.autoreload:/home/martin/PycharmProjects/Torque/models/views.py changed, reloading.
ERROR:django.request:Internal Server Error: /generate_csv/
Traceback (most recent call last):
  File "/home/martin/PycharmProjects/Torque/venv/lib/python3.8/site-packages/django/core/handlers/exception.py", line 47, in inner
    response = get_response(request)
  File "/home/martin/PycharmProjects/Torque/venv/lib/python3.8/site-packages/django/core/handlers/base.py", line 181, in _get_response
    response = wrapped_callback(request, *callback_args, **callback_kwargs)
  File "/home/martin/PycharmProjects/Torque/venv/lib/python3.8/site-packages/django/views/decorators/csrf.py", line 54, in wrapped_view
    return view_func(*args, **kwargs)
  File "/home/martin/PycharmProjects/Torque/models/views.py", line 526, in generate_custom_csv
    di
NameError: name 'di' is not defined
INFO:django.utils.autoreload:/home/martin/PycharmProjects/Torque/models/views.py changed, reloading.
ERROR:django.request:Internal Server Error: /generate_csv/
Traceback (most recent call last):
  File "/home/martin/PycharmProjects/Torque/venv/lib/python3.8/site-packages/django/core/handlers/exception.py", line 47, in inner
    response = get_response(request)
  File "/home/martin/PycharmProjects/Torque/venv/lib/python3.8/site-packages/django/core/handlers/base.py", line 181, in _get_response
    response = wrapped_callback(request, *callback_args, **callback_kwargs)
  File "/home/martin/PycharmProjects/Torque/venv/lib/python3.8/site-packages/django/views/decorators/csrf.py", line 54, in wrapped_view
    return view_func(*args, **kwargs)
  File "/home/martin/PycharmProjects/Torque/models/views.py", line 527, in generate_custom_csv
    dict_df(path_or_buf=response)
TypeError: 'DataFrame' object is not callable
INFO:django.utils.autoreload:/home/martin/PycharmProjects/Torque/models/views.py changed, reloading.
ERROR:django.request:Internal Server Error: /generate_csv/
Traceback (most recent call last):
  File "/home/martin/PycharmProjects/Torque/venv/lib/python3.8/site-packages/django/core/handlers/exception.py", line 47, in inner
    response = get_response(request)
  File "/home/martin/PycharmProjects/Torque/venv/lib/python3.8/site-packages/django/core/handlers/base.py", line 181, in _get_response
    response = wrapped_callback(request, *callback_args, **callback_kwargs)
  File "/home/martin/PycharmProjects/Torque/venv/lib/python3.8/site-packages/django/views/decorators/csrf.py", line 54, in wrapped_view
    return view_func(*args, **kwargs)
  File "/home/martin/PycharmProjects/Torque/models/views.py", line 527, in generate_custom_csv
    dict_df.to_excel(path_or_buf=response)
TypeError: to_excel() got an unexpected keyword argument 'path_or_buf'
INFO:django.utils.autoreload:/home/martin/PycharmProjects/Torque/models/views.py changed, reloading.
ERROR:django.request:Internal Server Error: /generate_csv/
Traceback (most recent call last):
  File "/home/martin/PycharmProjects/Torque/venv/lib/python3.8/site-packages/django/core/handlers/exception.py", line 47, in inner
    response = get_response(request)
  File "/home/martin/PycharmProjects/Torque/venv/lib/python3.8/site-packages/django/core/handlers/base.py", line 181, in _get_response
    response = wrapped_callback(request, *callback_args, **callback_kwargs)
  File "/home/martin/PycharmProjects/Torque/venv/lib/python3.8/site-packages/django/views/decorators/csrf.py", line 54, in wrapped_view
    return view_func(*args, **kwargs)
  File "/home/martin/PycharmProjects/Torque/models/views.py", line 527, in generate_custom_csv
    dict_df.to_html(path_or_buf=response)
TypeError: to_html() got an unexpected keyword argument 'path_or_buf'
INFO:django.utils.autoreload:/home/martin/PycharmProjects/Torque/models/views.py changed, reloading.
INFO:django.utils.autoreload:/home/martin/PycharmProjects/Torque/models/views.py changed, reloading.
INFO:django.utils.autoreload:/home/martin/PycharmProjects/Torque/models/views.py changed, reloading.
INFO:django.utils.autoreload:/home/martin/PycharmProjects/Torque/models/views.py changed, reloading.
INFO:django.utils.autoreload:/home/martin/PycharmProjects/Torque/models/views.py changed, reloading.
ERROR:django.request:Internal Server Error: /generate_csv/
Traceback (most recent call last):
  File "/home/martin/PycharmProjects/Torque/venv/lib/python3.8/site-packages/django/core/handlers/exception.py", line 47, in inner
    response = get_response(request)
  File "/home/martin/PycharmProjects/Torque/venv/lib/python3.8/site-packages/django/core/handlers/base.py", line 181, in _get_response
    response = wrapped_callback(request, *callback_args, **callback_kwargs)
  File "/home/martin/PycharmProjects/Torque/venv/lib/python3.8/site-packages/django/views/decorators/csrf.py", line 54, in wrapped_view
    return view_func(*args, **kwargs)
  File "/home/martin/PycharmProjects/Torque/models/views.py", line 525, in generate_custom_csv
    rq = HttpRequest('/generate_csv/')
TypeError: __init__() takes 1 positional argument but 2 were given
INFO:django.utils.autoreload:/home/martin/PycharmProjects/Torque/models/views.py changed, reloading.
ERROR:django.request:Internal Server Error: /generate_csv/
Traceback (most recent call last):
  File "/home/martin/PycharmProjects/Torque/venv/lib/python3.8/site-packages/django/core/handlers/exception.py", line 47, in inner
    response = get_response(request)
  File "/home/martin/PycharmProjects/Torque/venv/lib/python3.8/site-packages/django/core/handlers/base.py", line 181, in _get_response
    response = wrapped_callback(request, *callback_args, **callback_kwargs)
  File "/home/martin/PycharmProjects/Torque/venv/lib/python3.8/site-packages/django/views/decorators/csrf.py", line 54, in wrapped_view
    return view_func(*args, **kwargs)
  File "/home/martin/PycharmProjects/Torque/models/views.py", line 525, in generate_custom_csv
    rq = HttpRequest('/export_data/')
TypeError: __init__() takes 1 positional argument but 2 were given
INFO:django.utils.autoreload:/home/martin/PycharmProjects/Torque/models/views.py changed, reloading.
INFO:django.utils.autoreload:/home/martin/PycharmProjects/Torque/models/views.py changed, reloading.
ERROR:django.request:Internal Server Error: /generate_csv/
Traceback (most recent call last):
  File "/home/martin/PycharmProjects/Torque/venv/lib/python3.8/site-packages/django/core/handlers/exception.py", line 47, in inner
    response = get_response(request)
  File "/home/martin/PycharmProjects/Torque/venv/lib/python3.8/site-packages/django/core/handlers/base.py", line 181, in _get_response
    response = wrapped_callback(request, *callback_args, **callback_kwargs)
  File "/home/martin/PycharmProjects/Torque/venv/lib/python3.8/site-packages/django/views/decorators/csrf.py", line 54, in wrapped_view
    return view_func(*args, **kwargs)
  File "/home/martin/PycharmProjects/Torque/models/views.py", line 525, in generate_custom_csv
    rq = HttpRequest(url='/generate_csv/')
TypeError: __init__() got an unexpected keyword argument 'url'
ERROR:django.request:Internal Server Error: /generate_csv/
Traceback (most recent call last):
  File "/home/martin/PycharmProjects/Torque/venv/lib/python3.8/site-packages/django/core/handlers/exception.py", line 47, in inner
    response = get_response(request)
  File "/home/martin/PycharmProjects/Torque/venv/lib/python3.8/site-packages/django/core/handlers/base.py", line 181, in _get_response
    response = wrapped_callback(request, *callback_args, **callback_kwargs)
  File "/home/martin/PycharmProjects/Torque/venv/lib/python3.8/site-packages/django/views/decorators/csrf.py", line 54, in wrapped_view
    return view_func(*args, **kwargs)
  File "/home/martin/PycharmProjects/Torque/models/views.py", line 525, in generate_custom_csv
    rq = HttpRequest(url='/generate_csv/')
TypeError: __init__() got an unexpected keyword argument 'url'
INFO:django.utils.autoreload:/home/martin/PycharmProjects/Torque/models/views.py changed, reloading.
INFO:django.utils.autoreload:/home/martin/PycharmProjects/Torque/models/views.py changed, reloading.
ERROR:django.request:Internal Server Error: /generate_csv/
Traceback (most recent call last):
  File "/home/martin/PycharmProjects/Torque/venv/lib/python3.8/site-packages/django/core/handlers/exception.py", line 47, in inner
    response = get_response(request)
  File "/home/martin/PycharmProjects/Torque/venv/lib/python3.8/site-packages/django/utils/deprecation.py", line 116, in __call__
    response = self.process_response(request, response)
  File "/home/martin/PycharmProjects/Torque/venv/lib/python3.8/site-packages/django/middleware/clickjacking.py", line 26, in process_response
    if response.get('X-Frame-Options') is not None:
AttributeError: 'HttpRequest' object has no attribute 'get'
INFO:django.utils.autoreload:/home/martin/PycharmProjects/Torque/models/views.py changed, reloading.
INFO:django.utils.autoreload:/home/martin/PycharmProjects/Torque/models/views.py changed, reloading.
INFO:django.utils.autoreload:/home/martin/PycharmProjects/Torque/models/views.py changed, reloading.
INFO:django.utils.autoreload:/home/martin/PycharmProjects/Torque/models/views.py changed, reloading.
ERROR:django.request:Internal Server Error: /generate_csv
Traceback (most recent call last):
  File "/home/martin/PycharmProjects/Torque/venv/lib/python3.8/site-packages/django/core/handlers/exception.py", line 47, in inner
    response = get_response(request)
  File "/home/martin/PycharmProjects/Torque/venv/lib/python3.8/site-packages/django/utils/deprecation.py", line 113, in __call__
    response = self.process_request(request)
  File "/home/martin/PycharmProjects/Torque/venv/lib/python3.8/site-packages/django/middleware/common.py", line 54, in process_request
    path = self.get_full_path_with_slash(request)
  File "/home/martin/PycharmProjects/Torque/venv/lib/python3.8/site-packages/django/middleware/common.py", line 87, in get_full_path_with_slash
    raise RuntimeError(
RuntimeError: You called this URL via POST, but the URL doesn't end in a slash and you have APPEND_SLASH set. Django can't redirect to the slash URL while maintaining POST data. Change your form to point to localhost:8000/generate_csv/ (note the trailing slash), or set APPEND_SLASH=False in your Django settings.
WARNING:django.request:Not Found: /favicon.ico
ERROR:django.request:Internal Server Error: /generate_csv
Traceback (most recent call last):
  File "/home/martin/PycharmProjects/Torque/venv/lib/python3.8/site-packages/django/core/handlers/exception.py", line 47, in inner
    response = get_response(request)
  File "/home/martin/PycharmProjects/Torque/venv/lib/python3.8/site-packages/django/utils/deprecation.py", line 113, in __call__
    response = self.process_request(request)
  File "/home/martin/PycharmProjects/Torque/venv/lib/python3.8/site-packages/django/middleware/common.py", line 54, in process_request
    path = self.get_full_path_with_slash(request)
  File "/home/martin/PycharmProjects/Torque/venv/lib/python3.8/site-packages/django/middleware/common.py", line 87, in get_full_path_with_slash
    raise RuntimeError(
RuntimeError: You called this URL via POST, but the URL doesn't end in a slash and you have APPEND_SLASH set. Django can't redirect to the slash URL while maintaining POST data. Change your form to point to localhost:8000/generate_csv/ (note the trailing slash), or set APPEND_SLASH=False in your Django settings.
ERROR:django.request:Internal Server Error: /generate_csv/
Traceback (most recent call last):
  File "/home/martin/PycharmProjects/Torque/venv/lib/python3.8/site-packages/django/core/handlers/exception.py", line 47, in inner
    response = get_response(request)
  File "/home/martin/PycharmProjects/Torque/venv/lib/python3.8/site-packages/django/core/handlers/base.py", line 188, in _get_response
    self.check_response(response, callback)
  File "/home/martin/PycharmProjects/Torque/venv/lib/python3.8/site-packages/django/core/handlers/base.py", line 309, in check_response
    raise ValueError(
ValueError: The view models.views.generate_custom_csv didn't return an HttpResponse object. It returned None instead.
INFO:django.utils.autoreload:/home/martin/PycharmProjects/Torque/models/views.py changed, reloading.
ERROR:django.request:Internal Server Error: /generate_csv/
Traceback (most recent call last):
  File "/home/martin/PycharmProjects/Torque/venv/lib/python3.8/site-packages/django/core/handlers/exception.py", line 47, in inner
    response = get_response(request)
  File "/home/martin/PycharmProjects/Torque/venv/lib/python3.8/site-packages/django/core/handlers/base.py", line 188, in _get_response
    self.check_response(response, callback)
  File "/home/martin/PycharmProjects/Torque/venv/lib/python3.8/site-packages/django/core/handlers/base.py", line 309, in check_response
    raise ValueError(
ValueError: The view models.views.generate_custom_csv didn't return an HttpResponse object. It returned None instead.
ERROR:django.request:Internal Server Error: /generate_csv/
Traceback (most recent call last):
  File "/home/martin/PycharmProjects/Torque/venv/lib/python3.8/site-packages/django/core/handlers/exception.py", line 47, in inner
    response = get_response(request)
  File "/home/martin/PycharmProjects/Torque/venv/lib/python3.8/site-packages/django/core/handlers/base.py", line 188, in _get_response
    self.check_response(response, callback)
  File "/home/martin/PycharmProjects/Torque/venv/lib/python3.8/site-packages/django/core/handlers/base.py", line 309, in check_response
    raise ValueError(
ValueError: The view models.views.generate_custom_csv didn't return an HttpResponse object. It returned None instead.
INFO:django.utils.autoreload:/home/martin/PycharmProjects/Torque/models/views.py changed, reloading.
ERROR:django.request:Internal Server Error: /generate_csv/
Traceback (most recent call last):
  File "/home/martin/PycharmProjects/Torque/venv/lib/python3.8/site-packages/django/core/handlers/exception.py", line 47, in inner
    response = get_response(request)
  File "/home/martin/PycharmProjects/Torque/venv/lib/python3.8/site-packages/django/core/handlers/base.py", line 188, in _get_response
    self.check_response(response, callback)
  File "/home/martin/PycharmProjects/Torque/venv/lib/python3.8/site-packages/django/core/handlers/base.py", line 309, in check_response
    raise ValueError(
ValueError: The view models.views.generate_custom_csv didn't return an HttpResponse object. It returned None instead.
INFO:django.utils.autoreload:/home/martin/PycharmProjects/Torque/models/views.py changed, reloading.
INFO:django.utils.autoreload:/home/martin/PycharmProjects/Torque/models/views.py changed, reloading.
INFO:django.utils.autoreload:/home/martin/PycharmProjects/Torque/models/views.py changed, reloading.
INFO:django.utils.autoreload:/home/martin/PycharmProjects/Torque/models/views.py changed, reloading.
ERROR:django.request:Internal Server Error: /generate_csv/
Traceback (most recent call last):
  File "/home/martin/PycharmProjects/Torque/venv/lib/python3.8/site-packages/django/core/handlers/exception.py", line 47, in inner
    response = get_response(request)
  File "/home/martin/PycharmProjects/Torque/venv/lib/python3.8/site-packages/django/core/handlers/base.py", line 188, in _get_response
    self.check_response(response, callback)
  File "/home/martin/PycharmProjects/Torque/venv/lib/python3.8/site-packages/django/core/handlers/base.py", line 309, in check_response
    raise ValueError(
ValueError: The view models.views.generate_custom_csv didn't return an HttpResponse object. It returned None instead.
INFO:django.utils.autoreload:/home/martin/PycharmProjects/Torque/models/views.py changed, reloading.
ERROR:django.request:Internal Server Error: /generate_csv/
Traceback (most recent call last):
  File "/home/martin/PycharmProjects/Torque/venv/lib/python3.8/site-packages/django/core/handlers/exception.py", line 47, in inner
    response = get_response(request)
  File "/home/martin/PycharmProjects/Torque/venv/lib/python3.8/site-packages/django/core/handlers/base.py", line 188, in _get_response
    self.check_response(response, callback)
  File "/home/martin/PycharmProjects/Torque/venv/lib/python3.8/site-packages/django/core/handlers/base.py", line 309, in check_response
    raise ValueError(
ValueError: The view models.views.generate_custom_csv didn't return an HttpResponse object. It returned None instead.
INFO:django.utils.autoreload:/home/martin/PycharmProjects/Torque/models/views.py changed, reloading.
WARNING:django.security.csrf:Forbidden (CSRF token missing or incorrect.): /generate_csv/
WARNING:django.security.csrf:Forbidden (CSRF token missing or incorrect.): /generate_csv/
INFO:django.utils.autoreload:/home/martin/PycharmProjects/Torque/models/views.py changed, reloading.
ERROR:django.request:Internal Server Error: /generate_csv/
Traceback (most recent call last):
  File "/home/martin/PycharmProjects/Torque/venv/lib/python3.8/site-packages/django/core/handlers/exception.py", line 47, in inner
    response = get_response(request)
  File "/home/martin/PycharmProjects/Torque/venv/lib/python3.8/site-packages/django/core/handlers/base.py", line 188, in _get_response
    self.check_response(response, callback)
  File "/home/martin/PycharmProjects/Torque/venv/lib/python3.8/site-packages/django/core/handlers/base.py", line 309, in check_response
    raise ValueError(
ValueError: The view models.views.generate_custom_csv didn't return an HttpResponse object. It returned None instead.
INFO:django.utils.autoreload:/home/martin/PycharmProjects/Torque/models/views.py changed, reloading.
ERROR:django.request:Internal Server Error: /generate_csv/
Traceback (most recent call last):
  File "/home/martin/PycharmProjects/Torque/venv/lib/python3.8/site-packages/django/core/handlers/exception.py", line 47, in inner
    response = get_response(request)
  File "/home/martin/PycharmProjects/Torque/venv/lib/python3.8/site-packages/django/core/handlers/base.py", line 188, in _get_response
    self.check_response(response, callback)
  File "/home/martin/PycharmProjects/Torque/venv/lib/python3.8/site-packages/django/core/handlers/base.py", line 309, in check_response
    raise ValueError(
ValueError: The view models.views.generate_custom_csv didn't return an HttpResponse object. It returned None instead.
ERROR:django.request:Internal Server Error: /generate_csv/
Traceback (most recent call last):
  File "/home/martin/PycharmProjects/Torque/venv/lib/python3.8/site-packages/django/core/handlers/exception.py", line 47, in inner
    response = get_response(request)
  File "/home/martin/PycharmProjects/Torque/venv/lib/python3.8/site-packages/django/core/handlers/base.py", line 188, in _get_response
    self.check_response(response, callback)
  File "/home/martin/PycharmProjects/Torque/venv/lib/python3.8/site-packages/django/core/handlers/base.py", line 309, in check_response
    raise ValueError(
ValueError: The view models.views.generate_custom_csv didn't return an HttpResponse object. It returned None instead.
ERROR:django.request:Internal Server Error: /generate_csv/
Traceback (most recent call last):
  File "/home/martin/PycharmProjects/Torque/venv/lib/python3.8/site-packages/django/core/handlers/exception.py", line 47, in inner
    response = get_response(request)
  File "/home/martin/PycharmProjects/Torque/venv/lib/python3.8/site-packages/django/core/handlers/base.py", line 188, in _get_response
    self.check_response(response, callback)
  File "/home/martin/PycharmProjects/Torque/venv/lib/python3.8/site-packages/django/core/handlers/base.py", line 309, in check_response
    raise ValueError(
ValueError: The view models.views.generate_custom_csv didn't return an HttpResponse object. It returned None instead.
INFO:django.utils.autoreload:/home/martin/PycharmProjects/Torque/models/views.py changed, reloading.
ERROR:django.request:Internal Server Error: /generate_csv/
Traceback (most recent call last):
  File "/home/martin/PycharmProjects/Torque/venv/lib/python3.8/site-packages/django/core/handlers/exception.py", line 47, in inner
    response = get_response(request)
  File "/home/martin/PycharmProjects/Torque/venv/lib/python3.8/site-packages/django/core/handlers/base.py", line 188, in _get_response
    self.check_response(response, callback)
  File "/home/martin/PycharmProjects/Torque/venv/lib/python3.8/site-packages/django/core/handlers/base.py", line 309, in check_response
    raise ValueError(
ValueError: The view models.views.generate_custom_csv didn't return an HttpResponse object. It returned None instead.
ERROR:django.request:Internal Server Error: /generate_csv/
Traceback (most recent call last):
  File "/home/martin/PycharmProjects/Torque/venv/lib/python3.8/site-packages/django/core/handlers/exception.py", line 47, in inner
    response = get_response(request)
  File "/home/martin/PycharmProjects/Torque/venv/lib/python3.8/site-packages/django/core/handlers/base.py", line 188, in _get_response
    self.check_response(response, callback)
  File "/home/martin/PycharmProjects/Torque/venv/lib/python3.8/site-packages/django/core/handlers/base.py", line 309, in check_response
    raise ValueError(
ValueError: The view models.views.generate_custom_csv didn't return an HttpResponse object. It returned None instead.
INFO:django.utils.autoreload:/home/martin/PycharmProjects/Torque/models/views.py changed, reloading.
INFO:django.utils.autoreload:/home/martin/PycharmProjects/Torque/models/views.py changed, reloading.
ERROR:django.request:Internal Server Error: /generate_csv/
Traceback (most recent call last):
  File "/home/martin/PycharmProjects/Torque/venv/lib/python3.8/site-packages/django/core/handlers/exception.py", line 47, in inner
    response = get_response(request)
  File "/home/martin/PycharmProjects/Torque/venv/lib/python3.8/site-packages/django/core/handlers/base.py", line 188, in _get_response
    self.check_response(response, callback)
  File "/home/martin/PycharmProjects/Torque/venv/lib/python3.8/site-packages/django/core/handlers/base.py", line 309, in check_response
    raise ValueError(
ValueError: The view models.views.generate_custom_csv didn't return an HttpResponse object. It returned None instead.
INFO:django.utils.autoreload:/home/martin/PycharmProjects/Torque/models/views.py changed, reloading.
ERROR:django.request:Internal Server Error: /generate_csv/
Traceback (most recent call last):
  File "/home/martin/PycharmProjects/Torque/venv/lib/python3.8/site-packages/django/core/handlers/exception.py", line 47, in inner
    response = get_response(request)
  File "/home/martin/PycharmProjects/Torque/venv/lib/python3.8/site-packages/django/core/handlers/base.py", line 188, in _get_response
    self.check_response(response, callback)
  File "/home/martin/PycharmProjects/Torque/venv/lib/python3.8/site-packages/django/core/handlers/base.py", line 309, in check_response
    raise ValueError(
ValueError: The view models.views.generate_custom_csv didn't return an HttpResponse object. It returned None instead.
ERROR:django.request:Internal Server Error: /generate_csv/
Traceback (most recent call last):
  File "/home/martin/PycharmProjects/Torque/venv/lib/python3.8/site-packages/django/core/handlers/exception.py", line 47, in inner
    response = get_response(request)
  File "/home/martin/PycharmProjects/Torque/venv/lib/python3.8/site-packages/django/core/handlers/base.py", line 188, in _get_response
    self.check_response(response, callback)
  File "/home/martin/PycharmProjects/Torque/venv/lib/python3.8/site-packages/django/core/handlers/base.py", line 309, in check_response
    raise ValueError(
ValueError: The view models.views.generate_custom_csv didn't return an HttpResponse object. It returned None instead.
ERROR:django.request:Internal Server Error: /generate_csv/
Traceback (most recent call last):
  File "/home/martin/PycharmProjects/Torque/venv/lib/python3.8/site-packages/django/core/handlers/exception.py", line 47, in inner
    response = get_response(request)
  File "/home/martin/PycharmProjects/Torque/venv/lib/python3.8/site-packages/django/core/handlers/base.py", line 188, in _get_response
    self.check_response(response, callback)
  File "/home/martin/PycharmProjects/Torque/venv/lib/python3.8/site-packages/django/core/handlers/base.py", line 309, in check_response
    raise ValueError(
ValueError: The view models.views.generate_custom_csv didn't return an HttpResponse object. It returned None instead.
INFO:django.utils.autoreload:/home/martin/PycharmProjects/Torque/models/views.py changed, reloading.
INFO:django.utils.autoreload:/home/martin/PycharmProjects/Torque/models/views.py changed, reloading.
ERROR:django.request:Internal Server Error: /generate_csv/
Traceback (most recent call last):
  File "/home/martin/PycharmProjects/Torque/venv/lib/python3.8/site-packages/django/core/handlers/exception.py", line 47, in inner
    response = get_response(request)
  File "/home/martin/PycharmProjects/Torque/venv/lib/python3.8/site-packages/django/core/handlers/base.py", line 181, in _get_response
    response = wrapped_callback(request, *callback_args, **callback_kwargs)
  File "/home/martin/PycharmProjects/Torque/venv/lib/python3.8/site-packages/django/views/decorators/csrf.py", line 54, in wrapped_view
    return view_func(*args, **kwargs)
  File "/home/martin/PycharmProjects/Torque/models/views.py", line 473, in generate_custom_csv
    data = json.loads(request.body)
  File "/usr/lib/python3.8/json/__init__.py", line 357, in loads
    return _default_decoder.decode(s)
  File "/usr/lib/python3.8/json/decoder.py", line 337, in decode
    obj, end = self.raw_decode(s, idx=_w(s, 0).end())
  File "/usr/lib/python3.8/json/decoder.py", line 355, in raw_decode
    raise JSONDecodeError("Expecting value", s, err.value) from None
json.decoder.JSONDecodeError: Expecting value: line 1 column 1 (char 0)
INFO:django.utils.autoreload:/home/martin/PycharmProjects/Torque/models/views.py changed, reloading.
ERROR:django.request:Internal Server Error: /generate_csv/
Traceback (most recent call last):
  File "/home/martin/PycharmProjects/Torque/venv/lib/python3.8/site-packages/django/core/handlers/exception.py", line 47, in inner
    response = get_response(request)
  File "/home/martin/PycharmProjects/Torque/venv/lib/python3.8/site-packages/django/core/handlers/base.py", line 181, in _get_response
    response = wrapped_callback(request, *callback_args, **callback_kwargs)
  File "/home/martin/PycharmProjects/Torque/venv/lib/python3.8/site-packages/django/views/decorators/csrf.py", line 54, in wrapped_view
    return view_func(*args, **kwargs)
  File "/home/martin/PycharmProjects/Torque/models/views.py", line 473, in generate_custom_csv
    data = json.loads(request.body)
  File "/usr/lib/python3.8/json/__init__.py", line 357, in loads
    return _default_decoder.decode(s)
  File "/usr/lib/python3.8/json/decoder.py", line 337, in decode
    obj, end = self.raw_decode(s, idx=_w(s, 0).end())
  File "/usr/lib/python3.8/json/decoder.py", line 355, in raw_decode
    raise JSONDecodeError("Expecting value", s, err.value) from None
json.decoder.JSONDecodeError: Expecting value: line 1 column 1 (char 0)
ERROR:django.request:Internal Server Error: /generate_csv/
Traceback (most recent call last):
  File "/home/martin/PycharmProjects/Torque/venv/lib/python3.8/site-packages/django/core/handlers/exception.py", line 47, in inner
    response = get_response(request)
  File "/home/martin/PycharmProjects/Torque/venv/lib/python3.8/site-packages/django/core/handlers/base.py", line 181, in _get_response
    response = wrapped_callback(request, *callback_args, **callback_kwargs)
  File "/home/martin/PycharmProjects/Torque/venv/lib/python3.8/site-packages/django/views/decorators/csrf.py", line 54, in wrapped_view
    return view_func(*args, **kwargs)
  File "/home/martin/PycharmProjects/Torque/models/views.py", line 473, in generate_custom_csv
    data = json.loads(request.body)
  File "/usr/lib/python3.8/json/__init__.py", line 357, in loads
    return _default_decoder.decode(s)
  File "/usr/lib/python3.8/json/decoder.py", line 337, in decode
    obj, end = self.raw_decode(s, idx=_w(s, 0).end())
  File "/usr/lib/python3.8/json/decoder.py", line 355, in raw_decode
    raise JSONDecodeError("Expecting value", s, err.value) from None
json.decoder.JSONDecodeError: Expecting value: line 1 column 1 (char 0)
INFO:django.utils.autoreload:/home/martin/PycharmProjects/Torque/models/views.py changed, reloading.
ERROR:django.request:Internal Server Error: /generate_csv/
Traceback (most recent call last):
  File "/home/martin/PycharmProjects/Torque/venv/lib/python3.8/site-packages/django/core/handlers/exception.py", line 47, in inner
    response = get_response(request)
  File "/home/martin/PycharmProjects/Torque/venv/lib/python3.8/site-packages/django/core/handlers/base.py", line 181, in _get_response
    response = wrapped_callback(request, *callback_args, **callback_kwargs)
  File "/home/martin/PycharmProjects/Torque/venv/lib/python3.8/site-packages/django/views/decorators/csrf.py", line 54, in wrapped_view
    return view_func(*args, **kwargs)
  File "/home/martin/PycharmProjects/Torque/models/views.py", line 473, in generate_custom_csv
    data = json.loads(request.body)
  File "/usr/lib/python3.8/json/__init__.py", line 357, in loads
    return _default_decoder.decode(s)
  File "/usr/lib/python3.8/json/decoder.py", line 337, in decode
    obj, end = self.raw_decode(s, idx=_w(s, 0).end())
  File "/usr/lib/python3.8/json/decoder.py", line 355, in raw_decode
    raise JSONDecodeError("Expecting value", s, err.value) from None
json.decoder.JSONDecodeError: Expecting value: line 1 column 1 (char 0)
ERROR:django.request:Internal Server Error: /generate_csv/
Traceback (most recent call last):
  File "/home/martin/PycharmProjects/Torque/venv/lib/python3.8/site-packages/django/core/handlers/exception.py", line 47, in inner
    response = get_response(request)
  File "/home/martin/PycharmProjects/Torque/venv/lib/python3.8/site-packages/django/core/handlers/base.py", line 181, in _get_response
    response = wrapped_callback(request, *callback_args, **callback_kwargs)
  File "/home/martin/PycharmProjects/Torque/venv/lib/python3.8/site-packages/django/views/decorators/csrf.py", line 54, in wrapped_view
    return view_func(*args, **kwargs)
  File "/home/martin/PycharmProjects/Torque/models/views.py", line 473, in generate_custom_csv
    data = json.loads(request.body)
  File "/usr/lib/python3.8/json/__init__.py", line 357, in loads
    return _default_decoder.decode(s)
  File "/usr/lib/python3.8/json/decoder.py", line 337, in decode
    obj, end = self.raw_decode(s, idx=_w(s, 0).end())
  File "/usr/lib/python3.8/json/decoder.py", line 355, in raw_decode
    raise JSONDecodeError("Expecting value", s, err.value) from None
json.decoder.JSONDecodeError: Expecting value: line 1 column 1 (char 0)
ERROR:django.request:Internal Server Error: /generate_csv/
Traceback (most recent call last):
  File "/home/martin/PycharmProjects/Torque/venv/lib/python3.8/site-packages/django/core/handlers/exception.py", line 47, in inner
    response = get_response(request)
  File "/home/martin/PycharmProjects/Torque/venv/lib/python3.8/site-packages/django/core/handlers/base.py", line 181, in _get_response
    response = wrapped_callback(request, *callback_args, **callback_kwargs)
  File "/home/martin/PycharmProjects/Torque/venv/lib/python3.8/site-packages/django/views/decorators/csrf.py", line 54, in wrapped_view
    return view_func(*args, **kwargs)
  File "/home/martin/PycharmProjects/Torque/models/views.py", line 473, in generate_custom_csv
    data = json.loads(request.body)
  File "/usr/lib/python3.8/json/__init__.py", line 357, in loads
    return _default_decoder.decode(s)
  File "/usr/lib/python3.8/json/decoder.py", line 337, in decode
    obj, end = self.raw_decode(s, idx=_w(s, 0).end())
  File "/usr/lib/python3.8/json/decoder.py", line 355, in raw_decode
    raise JSONDecodeError("Expecting value", s, err.value) from None
json.decoder.JSONDecodeError: Expecting value: line 1 column 1 (char 0)
ERROR:django.request:Internal Server Error: /generate_csv/
Traceback (most recent call last):
  File "/home/martin/PycharmProjects/Torque/venv/lib/python3.8/site-packages/django/core/handlers/exception.py", line 47, in inner
    response = get_response(request)
  File "/home/martin/PycharmProjects/Torque/venv/lib/python3.8/site-packages/django/core/handlers/base.py", line 181, in _get_response
    response = wrapped_callback(request, *callback_args, **callback_kwargs)
  File "/home/martin/PycharmProjects/Torque/venv/lib/python3.8/site-packages/django/views/decorators/csrf.py", line 54, in wrapped_view
    return view_func(*args, **kwargs)
  File "/home/martin/PycharmProjects/Torque/models/views.py", line 473, in generate_custom_csv
    data = json.loads(request.body)
  File "/usr/lib/python3.8/json/__init__.py", line 357, in loads
    return _default_decoder.decode(s)
  File "/usr/lib/python3.8/json/decoder.py", line 337, in decode
    obj, end = self.raw_decode(s, idx=_w(s, 0).end())
  File "/usr/lib/python3.8/json/decoder.py", line 355, in raw_decode
    raise JSONDecodeError("Expecting value", s, err.value) from None
json.decoder.JSONDecodeError: Expecting value: line 1 column 1 (char 0)
INFO:django.utils.autoreload:/home/martin/PycharmProjects/Torque/models/views.py changed, reloading.
INFO:django.utils.autoreload:/home/martin/PycharmProjects/Torque/models/views.py changed, reloading.
INFO:django.utils.autoreload:/home/martin/PycharmProjects/Torque/models/views.py changed, reloading.
ERROR:django.request:Internal Server Error: /generate_csv/
Traceback (most recent call last):
  File "/home/martin/PycharmProjects/Torque/venv/lib/python3.8/site-packages/django/core/handlers/exception.py", line 47, in inner
    response = get_response(request)
  File "/home/martin/PycharmProjects/Torque/venv/lib/python3.8/site-packages/django/core/handlers/base.py", line 181, in _get_response
    response = wrapped_callback(request, *callback_args, **callback_kwargs)
  File "/home/martin/PycharmProjects/Torque/venv/lib/python3.8/site-packages/django/views/decorators/csrf.py", line 54, in wrapped_view
    return view_func(*args, **kwargs)
  File "/home/martin/PycharmProjects/Torque/models/views.py", line 476, in generate_custom_csv
    id_sensors = [value for key, value in request.POST.items() if key.contains('sensor')]
  File "/home/martin/PycharmProjects/Torque/models/views.py", line 476, in <listcomp>
    id_sensors = [value for key, value in request.POST.items() if key.contains('sensor')]
AttributeError: 'str' object has no attribute 'contains'
INFO:django.utils.autoreload:/home/martin/PycharmProjects/Torque/models/views.py changed, reloading.
INFO:django.utils.autoreload:/home/martin/PycharmProjects/Torque/models/views.py changed, reloading.
INFO:django.utils.autoreload:/home/martin/PycharmProjects/Torque/models/views.py changed, reloading.
INFO:root:TRACKING_ALL_SESSIONS STARTED
INFO:root:Se vacia la tabla TrackLog para volver a obtener los nombres de las calles de todas las sesiones
INFO:root:TRACKING_ALL_SESSIONS STARTED
ERROR:django.request:Internal Server Error: /track_all_sessions
Traceback (most recent call last):
  File "/home/martin/PycharmProjects/Torque/venv/lib/python3.8/site-packages/django/db/backends/utils.py", line 84, in _execute
    return self.cursor.execute(sql, params)
  File "/home/martin/PycharmProjects/Torque/venv/lib/python3.8/site-packages/django/db/backends/mysql/base.py", line 73, in execute
    return self.cursor.execute(query, args)
  File "/home/martin/PycharmProjects/Torque/venv/lib/python3.8/site-packages/pymysql/cursors.py", line 148, in execute
    result = self._query(query)
  File "/home/martin/PycharmProjects/Torque/venv/lib/python3.8/site-packages/pymysql/cursors.py", line 310, in _query
    conn.query(q)
  File "/home/martin/PycharmProjects/Torque/venv/lib/python3.8/site-packages/pymysql/connections.py", line 548, in query
    self._affected_rows = self._read_query_result(unbuffered=unbuffered)
  File "/home/martin/PycharmProjects/Torque/venv/lib/python3.8/site-packages/pymysql/connections.py", line 775, in _read_query_result
    result.read()
  File "/home/martin/PycharmProjects/Torque/venv/lib/python3.8/site-packages/pymysql/connections.py", line 1156, in read
    first_packet = self.connection._read_packet()
  File "/home/martin/PycharmProjects/Torque/venv/lib/python3.8/site-packages/pymysql/connections.py", line 725, in _read_packet
    packet.raise_for_error()
  File "/home/martin/PycharmProjects/Torque/venv/lib/python3.8/site-packages/pymysql/protocol.py", line 221, in raise_for_error
    err.raise_mysql_exception(self._data)
  File "/home/martin/PycharmProjects/Torque/venv/lib/python3.8/site-packages/pymysql/err.py", line 143, in raise_mysql_exception
    raise errorclass(errno, errval)
pymysql.err.OperationalError: (1205, 'Lock wait timeout exceeded; try restarting transaction')

The above exception was the direct cause of the following exception:

Traceback (most recent call last):
  File "/home/martin/PycharmProjects/Torque/venv/lib/python3.8/site-packages/django/core/handlers/exception.py", line 47, in inner
    response = get_response(request)
  File "/home/martin/PycharmProjects/Torque/venv/lib/python3.8/site-packages/django/core/handlers/base.py", line 181, in _get_response
    response = wrapped_callback(request, *callback_args, **callback_kwargs)
  File "/home/martin/PycharmProjects/Torque/models/views.py", line 73, in tracking_all_sessions
    TrackLog.objects.all().delete()
  File "/home/martin/PycharmProjects/Torque/venv/lib/python3.8/site-packages/django/db/models/query.py", line 747, in delete
    deleted, _rows_count = collector.delete()
  File "/home/martin/PycharmProjects/Torque/venv/lib/python3.8/site-packages/django/db/models/deletion.py", line 410, in delete
    count = qs._raw_delete(using=self.using)
  File "/home/martin/PycharmProjects/Torque/venv/lib/python3.8/site-packages/django/db/models/query.py", line 763, in _raw_delete
    cursor = query.get_compiler(using).execute_sql(CURSOR)
  File "/home/martin/PycharmProjects/Torque/venv/lib/python3.8/site-packages/django/db/models/sql/compiler.py", line 1156, in execute_sql
    cursor.execute(sql, params)
  File "/home/martin/PycharmProjects/Torque/venv/lib/python3.8/site-packages/django/db/backends/utils.py", line 98, in execute
    return super().execute(sql, params)
  File "/home/martin/PycharmProjects/Torque/venv/lib/python3.8/site-packages/django/db/backends/utils.py", line 66, in execute
    return self._execute_with_wrappers(sql, params, many=False, executor=self._execute)
  File "/home/martin/PycharmProjects/Torque/venv/lib/python3.8/site-packages/django/db/backends/utils.py", line 75, in _execute_with_wrappers
    return executor(sql, params, many, context)
  File "/home/martin/PycharmProjects/Torque/venv/lib/python3.8/site-packages/django/db/backends/utils.py", line 84, in _execute
    return self.cursor.execute(sql, params)
  File "/home/martin/PycharmProjects/Torque/venv/lib/python3.8/site-packages/django/db/utils.py", line 90, in __exit__
    raise dj_exc_value.with_traceback(traceback) from exc_value
  File "/home/martin/PycharmProjects/Torque/venv/lib/python3.8/site-packages/django/db/backends/utils.py", line 84, in _execute
    return self.cursor.execute(sql, params)
  File "/home/martin/PycharmProjects/Torque/venv/lib/python3.8/site-packages/django/db/backends/mysql/base.py", line 73, in execute
    return self.cursor.execute(query, args)
  File "/home/martin/PycharmProjects/Torque/venv/lib/python3.8/site-packages/pymysql/cursors.py", line 148, in execute
    result = self._query(query)
  File "/home/martin/PycharmProjects/Torque/venv/lib/python3.8/site-packages/pymysql/cursors.py", line 310, in _query
    conn.query(q)
  File "/home/martin/PycharmProjects/Torque/venv/lib/python3.8/site-packages/pymysql/connections.py", line 548, in query
    self._affected_rows = self._read_query_result(unbuffered=unbuffered)
  File "/home/martin/PycharmProjects/Torque/venv/lib/python3.8/site-packages/pymysql/connections.py", line 775, in _read_query_result
    result.read()
  File "/home/martin/PycharmProjects/Torque/venv/lib/python3.8/site-packages/pymysql/connections.py", line 1156, in read
    first_packet = self.connection._read_packet()
  File "/home/martin/PycharmProjects/Torque/venv/lib/python3.8/site-packages/pymysql/connections.py", line 725, in _read_packet
    packet.raise_for_error()
  File "/home/martin/PycharmProjects/Torque/venv/lib/python3.8/site-packages/pymysql/protocol.py", line 221, in raise_for_error
    err.raise_mysql_exception(self._data)
  File "/home/martin/PycharmProjects/Torque/venv/lib/python3.8/site-packages/pymysql/err.py", line 143, in raise_mysql_exception
    raise errorclass(errno, errval)
django.db.utils.OperationalError: (1205, 'Lock wait timeout exceeded; try restarting transaction')
WARNING:django.request:Not Found: /favicon.ico
INFO:root:TRACKING_ALL_SESSIONS STARTED
ERROR:django.request:Internal Server Error: /track_all_sessions
Traceback (most recent call last):
  File "/home/martin/PycharmProjects/Torque/venv/lib/python3.8/site-packages/django/db/backends/utils.py", line 84, in _execute
    return self.cursor.execute(sql, params)
  File "/home/martin/PycharmProjects/Torque/venv/lib/python3.8/site-packages/django/db/backends/mysql/base.py", line 73, in execute
    return self.cursor.execute(query, args)
  File "/home/martin/PycharmProjects/Torque/venv/lib/python3.8/site-packages/pymysql/cursors.py", line 148, in execute
    result = self._query(query)
  File "/home/martin/PycharmProjects/Torque/venv/lib/python3.8/site-packages/pymysql/cursors.py", line 310, in _query
    conn.query(q)
  File "/home/martin/PycharmProjects/Torque/venv/lib/python3.8/site-packages/pymysql/connections.py", line 548, in query
    self._affected_rows = self._read_query_result(unbuffered=unbuffered)
  File "/home/martin/PycharmProjects/Torque/venv/lib/python3.8/site-packages/pymysql/connections.py", line 775, in _read_query_result
    result.read()
  File "/home/martin/PycharmProjects/Torque/venv/lib/python3.8/site-packages/pymysql/connections.py", line 1156, in read
    first_packet = self.connection._read_packet()
  File "/home/martin/PycharmProjects/Torque/venv/lib/python3.8/site-packages/pymysql/connections.py", line 725, in _read_packet
    packet.raise_for_error()
  File "/home/martin/PycharmProjects/Torque/venv/lib/python3.8/site-packages/pymysql/protocol.py", line 221, in raise_for_error
    err.raise_mysql_exception(self._data)
  File "/home/martin/PycharmProjects/Torque/venv/lib/python3.8/site-packages/pymysql/err.py", line 143, in raise_mysql_exception
    raise errorclass(errno, errval)
pymysql.err.OperationalError: (1205, 'Lock wait timeout exceeded; try restarting transaction')

The above exception was the direct cause of the following exception:

Traceback (most recent call last):
  File "/home/martin/PycharmProjects/Torque/venv/lib/python3.8/site-packages/django/core/handlers/exception.py", line 47, in inner
    response = get_response(request)
  File "/home/martin/PycharmProjects/Torque/venv/lib/python3.8/site-packages/django/core/handlers/base.py", line 181, in _get_response
    response = wrapped_callback(request, *callback_args, **callback_kwargs)
  File "/home/martin/PycharmProjects/Torque/models/views.py", line 73, in tracking_all_sessions
    TrackLog.objects.all().delete()
  File "/home/martin/PycharmProjects/Torque/venv/lib/python3.8/site-packages/django/db/models/query.py", line 747, in delete
    deleted, _rows_count = collector.delete()
  File "/home/martin/PycharmProjects/Torque/venv/lib/python3.8/site-packages/django/db/models/deletion.py", line 410, in delete
    count = qs._raw_delete(using=self.using)
  File "/home/martin/PycharmProjects/Torque/venv/lib/python3.8/site-packages/django/db/models/query.py", line 763, in _raw_delete
    cursor = query.get_compiler(using).execute_sql(CURSOR)
  File "/home/martin/PycharmProjects/Torque/venv/lib/python3.8/site-packages/django/db/models/sql/compiler.py", line 1156, in execute_sql
    cursor.execute(sql, params)
  File "/home/martin/PycharmProjects/Torque/venv/lib/python3.8/site-packages/django/db/backends/utils.py", line 98, in execute
    return super().execute(sql, params)
  File "/home/martin/PycharmProjects/Torque/venv/lib/python3.8/site-packages/django/db/backends/utils.py", line 66, in execute
    return self._execute_with_wrappers(sql, params, many=False, executor=self._execute)
  File "/home/martin/PycharmProjects/Torque/venv/lib/python3.8/site-packages/django/db/backends/utils.py", line 75, in _execute_with_wrappers
    return executor(sql, params, many, context)
  File "/home/martin/PycharmProjects/Torque/venv/lib/python3.8/site-packages/django/db/backends/utils.py", line 84, in _execute
    return self.cursor.execute(sql, params)
  File "/home/martin/PycharmProjects/Torque/venv/lib/python3.8/site-packages/django/db/utils.py", line 90, in __exit__
    raise dj_exc_value.with_traceback(traceback) from exc_value
  File "/home/martin/PycharmProjects/Torque/venv/lib/python3.8/site-packages/django/db/backends/utils.py", line 84, in _execute
    return self.cursor.execute(sql, params)
  File "/home/martin/PycharmProjects/Torque/venv/lib/python3.8/site-packages/django/db/backends/mysql/base.py", line 73, in execute
    return self.cursor.execute(query, args)
  File "/home/martin/PycharmProjects/Torque/venv/lib/python3.8/site-packages/pymysql/cursors.py", line 148, in execute
    result = self._query(query)
  File "/home/martin/PycharmProjects/Torque/venv/lib/python3.8/site-packages/pymysql/cursors.py", line 310, in _query
    conn.query(q)
  File "/home/martin/PycharmProjects/Torque/venv/lib/python3.8/site-packages/pymysql/connections.py", line 548, in query
    self._affected_rows = self._read_query_result(unbuffered=unbuffered)
  File "/home/martin/PycharmProjects/Torque/venv/lib/python3.8/site-packages/pymysql/connections.py", line 775, in _read_query_result
    result.read()
  File "/home/martin/PycharmProjects/Torque/venv/lib/python3.8/site-packages/pymysql/connections.py", line 1156, in read
    first_packet = self.connection._read_packet()
  File "/home/martin/PycharmProjects/Torque/venv/lib/python3.8/site-packages/pymysql/connections.py", line 725, in _read_packet
    packet.raise_for_error()
  File "/home/martin/PycharmProjects/Torque/venv/lib/python3.8/site-packages/pymysql/protocol.py", line 221, in raise_for_error
    err.raise_mysql_exception(self._data)
  File "/home/martin/PycharmProjects/Torque/venv/lib/python3.8/site-packages/pymysql/err.py", line 143, in raise_mysql_exception
    raise errorclass(errno, errval)
django.db.utils.OperationalError: (1205, 'Lock wait timeout exceeded; try restarting transaction')
INFO:root:TRACKING_ALL_SESSIONS STARTED
INFO:root:TRACKING_ALL_SESSIONS STARTED
ERROR:django.request:Internal Server Error: /track_all_sessions
Traceback (most recent call last):
  File "/home/martin/PycharmProjects/Torque/venv/lib/python3.8/site-packages/django/db/backends/utils.py", line 84, in _execute
    return self.cursor.execute(sql, params)
  File "/home/martin/PycharmProjects/Torque/venv/lib/python3.8/site-packages/django/db/backends/mysql/base.py", line 73, in execute
    return self.cursor.execute(query, args)
  File "/home/martin/PycharmProjects/Torque/venv/lib/python3.8/site-packages/pymysql/cursors.py", line 148, in execute
    result = self._query(query)
  File "/home/martin/PycharmProjects/Torque/venv/lib/python3.8/site-packages/pymysql/cursors.py", line 310, in _query
    conn.query(q)
  File "/home/martin/PycharmProjects/Torque/venv/lib/python3.8/site-packages/pymysql/connections.py", line 548, in query
    self._affected_rows = self._read_query_result(unbuffered=unbuffered)
  File "/home/martin/PycharmProjects/Torque/venv/lib/python3.8/site-packages/pymysql/connections.py", line 775, in _read_query_result
    result.read()
  File "/home/martin/PycharmProjects/Torque/venv/lib/python3.8/site-packages/pymysql/connections.py", line 1156, in read
    first_packet = self.connection._read_packet()
  File "/home/martin/PycharmProjects/Torque/venv/lib/python3.8/site-packages/pymysql/connections.py", line 725, in _read_packet
    packet.raise_for_error()
  File "/home/martin/PycharmProjects/Torque/venv/lib/python3.8/site-packages/pymysql/protocol.py", line 221, in raise_for_error
    err.raise_mysql_exception(self._data)
  File "/home/martin/PycharmProjects/Torque/venv/lib/python3.8/site-packages/pymysql/err.py", line 143, in raise_mysql_exception
    raise errorclass(errno, errval)
pymysql.err.OperationalError: (1205, 'Lock wait timeout exceeded; try restarting transaction')

The above exception was the direct cause of the following exception:

Traceback (most recent call last):
  File "/home/martin/PycharmProjects/Torque/venv/lib/python3.8/site-packages/django/core/handlers/exception.py", line 47, in inner
    response = get_response(request)
  File "/home/martin/PycharmProjects/Torque/venv/lib/python3.8/site-packages/django/core/handlers/base.py", line 181, in _get_response
    response = wrapped_callback(request, *callback_args, **callback_kwargs)
  File "/home/martin/PycharmProjects/Torque/models/views.py", line 73, in tracking_all_sessions
    TrackLog.objects.all().delete()
  File "/home/martin/PycharmProjects/Torque/venv/lib/python3.8/site-packages/django/db/models/query.py", line 747, in delete
    deleted, _rows_count = collector.delete()
  File "/home/martin/PycharmProjects/Torque/venv/lib/python3.8/site-packages/django/db/models/deletion.py", line 410, in delete
    count = qs._raw_delete(using=self.using)
  File "/home/martin/PycharmProjects/Torque/venv/lib/python3.8/site-packages/django/db/models/query.py", line 763, in _raw_delete
    cursor = query.get_compiler(using).execute_sql(CURSOR)
  File "/home/martin/PycharmProjects/Torque/venv/lib/python3.8/site-packages/django/db/models/sql/compiler.py", line 1156, in execute_sql
    cursor.execute(sql, params)
  File "/home/martin/PycharmProjects/Torque/venv/lib/python3.8/site-packages/django/db/backends/utils.py", line 98, in execute
    return super().execute(sql, params)
  File "/home/martin/PycharmProjects/Torque/venv/lib/python3.8/site-packages/django/db/backends/utils.py", line 66, in execute
    return self._execute_with_wrappers(sql, params, many=False, executor=self._execute)
  File "/home/martin/PycharmProjects/Torque/venv/lib/python3.8/site-packages/django/db/backends/utils.py", line 75, in _execute_with_wrappers
    return executor(sql, params, many, context)
  File "/home/martin/PycharmProjects/Torque/venv/lib/python3.8/site-packages/django/db/backends/utils.py", line 84, in _execute
    return self.cursor.execute(sql, params)
  File "/home/martin/PycharmProjects/Torque/venv/lib/python3.8/site-packages/django/db/utils.py", line 90, in __exit__
    raise dj_exc_value.with_traceback(traceback) from exc_value
  File "/home/martin/PycharmProjects/Torque/venv/lib/python3.8/site-packages/django/db/backends/utils.py", line 84, in _execute
    return self.cursor.execute(sql, params)
  File "/home/martin/PycharmProjects/Torque/venv/lib/python3.8/site-packages/django/db/backends/mysql/base.py", line 73, in execute
    return self.cursor.execute(query, args)
  File "/home/martin/PycharmProjects/Torque/venv/lib/python3.8/site-packages/pymysql/cursors.py", line 148, in execute
    result = self._query(query)
  File "/home/martin/PycharmProjects/Torque/venv/lib/python3.8/site-packages/pymysql/cursors.py", line 310, in _query
    conn.query(q)
  File "/home/martin/PycharmProjects/Torque/venv/lib/python3.8/site-packages/pymysql/connections.py", line 548, in query
    self._affected_rows = self._read_query_result(unbuffered=unbuffered)
  File "/home/martin/PycharmProjects/Torque/venv/lib/python3.8/site-packages/pymysql/connections.py", line 775, in _read_query_result
    result.read()
  File "/home/martin/PycharmProjects/Torque/venv/lib/python3.8/site-packages/pymysql/connections.py", line 1156, in read
    first_packet = self.connection._read_packet()
  File "/home/martin/PycharmProjects/Torque/venv/lib/python3.8/site-packages/pymysql/connections.py", line 725, in _read_packet
    packet.raise_for_error()
  File "/home/martin/PycharmProjects/Torque/venv/lib/python3.8/site-packages/pymysql/protocol.py", line 221, in raise_for_error
    err.raise_mysql_exception(self._data)
  File "/home/martin/PycharmProjects/Torque/venv/lib/python3.8/site-packages/pymysql/err.py", line 143, in raise_mysql_exception
    raise errorclass(errno, errval)
django.db.utils.OperationalError: (1205, 'Lock wait timeout exceeded; try restarting transaction')
ERROR:django.request:Internal Server Error: /track_all_sessions
Traceback (most recent call last):
  File "/home/martin/PycharmProjects/Torque/venv/lib/python3.8/site-packages/django/db/backends/utils.py", line 84, in _execute
    return self.cursor.execute(sql, params)
  File "/home/martin/PycharmProjects/Torque/venv/lib/python3.8/site-packages/django/db/backends/mysql/base.py", line 73, in execute
    return self.cursor.execute(query, args)
  File "/home/martin/PycharmProjects/Torque/venv/lib/python3.8/site-packages/pymysql/cursors.py", line 148, in execute
    result = self._query(query)
  File "/home/martin/PycharmProjects/Torque/venv/lib/python3.8/site-packages/pymysql/cursors.py", line 310, in _query
    conn.query(q)
  File "/home/martin/PycharmProjects/Torque/venv/lib/python3.8/site-packages/pymysql/connections.py", line 548, in query
    self._affected_rows = self._read_query_result(unbuffered=unbuffered)
  File "/home/martin/PycharmProjects/Torque/venv/lib/python3.8/site-packages/pymysql/connections.py", line 775, in _read_query_result
    result.read()
  File "/home/martin/PycharmProjects/Torque/venv/lib/python3.8/site-packages/pymysql/connections.py", line 1156, in read
    first_packet = self.connection._read_packet()
  File "/home/martin/PycharmProjects/Torque/venv/lib/python3.8/site-packages/pymysql/connections.py", line 725, in _read_packet
    packet.raise_for_error()
  File "/home/martin/PycharmProjects/Torque/venv/lib/python3.8/site-packages/pymysql/protocol.py", line 221, in raise_for_error
    err.raise_mysql_exception(self._data)
  File "/home/martin/PycharmProjects/Torque/venv/lib/python3.8/site-packages/pymysql/err.py", line 143, in raise_mysql_exception
    raise errorclass(errno, errval)
pymysql.err.OperationalError: (1205, 'Lock wait timeout exceeded; try restarting transaction')

The above exception was the direct cause of the following exception:

Traceback (most recent call last):
  File "/home/martin/PycharmProjects/Torque/venv/lib/python3.8/site-packages/django/core/handlers/exception.py", line 47, in inner
    response = get_response(request)
  File "/home/martin/PycharmProjects/Torque/venv/lib/python3.8/site-packages/django/core/handlers/base.py", line 181, in _get_response
    response = wrapped_callback(request, *callback_args, **callback_kwargs)
  File "/home/martin/PycharmProjects/Torque/models/views.py", line 73, in tracking_all_sessions
    TrackLog.objects.all().delete()
  File "/home/martin/PycharmProjects/Torque/venv/lib/python3.8/site-packages/django/db/models/query.py", line 747, in delete
    deleted, _rows_count = collector.delete()
  File "/home/martin/PycharmProjects/Torque/venv/lib/python3.8/site-packages/django/db/models/deletion.py", line 410, in delete
    count = qs._raw_delete(using=self.using)
  File "/home/martin/PycharmProjects/Torque/venv/lib/python3.8/site-packages/django/db/models/query.py", line 763, in _raw_delete
    cursor = query.get_compiler(using).execute_sql(CURSOR)
  File "/home/martin/PycharmProjects/Torque/venv/lib/python3.8/site-packages/django/db/models/sql/compiler.py", line 1156, in execute_sql
    cursor.execute(sql, params)
  File "/home/martin/PycharmProjects/Torque/venv/lib/python3.8/site-packages/django/db/backends/utils.py", line 98, in execute
    return super().execute(sql, params)
  File "/home/martin/PycharmProjects/Torque/venv/lib/python3.8/site-packages/django/db/backends/utils.py", line 66, in execute
    return self._execute_with_wrappers(sql, params, many=False, executor=self._execute)
  File "/home/martin/PycharmProjects/Torque/venv/lib/python3.8/site-packages/django/db/backends/utils.py", line 75, in _execute_with_wrappers
    return executor(sql, params, many, context)
  File "/home/martin/PycharmProjects/Torque/venv/lib/python3.8/site-packages/django/db/backends/utils.py", line 84, in _execute
    return self.cursor.execute(sql, params)
  File "/home/martin/PycharmProjects/Torque/venv/lib/python3.8/site-packages/django/db/utils.py", line 90, in __exit__
    raise dj_exc_value.with_traceback(traceback) from exc_value
  File "/home/martin/PycharmProjects/Torque/venv/lib/python3.8/site-packages/django/db/backends/utils.py", line 84, in _execute
    return self.cursor.execute(sql, params)
  File "/home/martin/PycharmProjects/Torque/venv/lib/python3.8/site-packages/django/db/backends/mysql/base.py", line 73, in execute
    return self.cursor.execute(query, args)
  File "/home/martin/PycharmProjects/Torque/venv/lib/python3.8/site-packages/pymysql/cursors.py", line 148, in execute
    result = self._query(query)
  File "/home/martin/PycharmProjects/Torque/venv/lib/python3.8/site-packages/pymysql/cursors.py", line 310, in _query
    conn.query(q)
  File "/home/martin/PycharmProjects/Torque/venv/lib/python3.8/site-packages/pymysql/connections.py", line 548, in query
    self._affected_rows = self._read_query_result(unbuffered=unbuffered)
  File "/home/martin/PycharmProjects/Torque/venv/lib/python3.8/site-packages/pymysql/connections.py", line 775, in _read_query_result
    result.read()
  File "/home/martin/PycharmProjects/Torque/venv/lib/python3.8/site-packages/pymysql/connections.py", line 1156, in read
    first_packet = self.connection._read_packet()
  File "/home/martin/PycharmProjects/Torque/venv/lib/python3.8/site-packages/pymysql/connections.py", line 725, in _read_packet
    packet.raise_for_error()
  File "/home/martin/PycharmProjects/Torque/venv/lib/python3.8/site-packages/pymysql/protocol.py", line 221, in raise_for_error
    err.raise_mysql_exception(self._data)
  File "/home/martin/PycharmProjects/Torque/venv/lib/python3.8/site-packages/pymysql/err.py", line 143, in raise_mysql_exception
    raise errorclass(errno, errval)
django.db.utils.OperationalError: (1205, 'Lock wait timeout exceeded; try restarting transaction')
INFO:root:TRACKING_ALL_SESSIONS STARTED
INFO:root:Se vacia la tabla TrackLog para volver a obtener los nombres de las calles de todas las sesiones
INFO:root:SEPARE_SESSIONS STARTED 
INFO:root:De la sesion 10 se actualizaron 0 registros
INFO:root:De la sesion 25 se actualizaron 0 registros
INFO:root:De la sesion 29 se actualizaron 0 registros
INFO:root:De la sesion 41 se actualizaron 0 registros
INFO:root:De la sesion 57 se actualizaron 0 registros
INFO:root:De la sesion 66 se actualizaron 0 registros
INFO:root:De la sesion 70 se actualizaron 0 registros
INFO:django.utils.autoreload:/home/martin/PycharmProjects/Torque/models/views.py changed, reloading.
INFO:root:SEPARE_SESSIONS STARTED 
INFO:root:De la sesion 10 se actualizaron 0 registros
INFO:django.utils.autoreload:/home/martin/PycharmProjects/Torque/models/views.py changed, reloading.
INFO:root:SEPARE_SESSIONS STARTED 
INFO:root:De la sesion 10 se actualizaron 0 registros
INFO:root:De la sesion 25 se actualizaron 0 registros
INFO:root:De la sesion 29 se actualizaron 0 registros
INFO:django.utils.autoreload:/home/martin/PycharmProjects/Torque/models/views.py changed, reloading.
INFO:root:SEPARE_SESSIONS STARTED 
INFO:root:De la sesion 10 se actualizaron 0 registros
INFO:root:De la sesion 25 se actualizaron 0 registros
INFO:root:De la sesion 29 se actualizaron 0 registros
INFO:root:De la sesion 41 se actualizaron 0 registros
INFO:root:De la sesion 57 se actualizaron 0 registros
INFO:root:De la sesion 66 se actualizaron 0 registros
INFO:root:De la sesion 70 se actualizaron 0 registros
INFO:root:De la sesion 81 se actualizaron 0 registros
INFO:root:De la sesion 213 se actualizaron 0 registros
INFO:root:De la sesion 280 se actualizaron 0 registros
INFO:root:De la sesion 300 se actualizaron 0 registros
INFO:root:De la sesion 311 se actualizaron 0 registros
INFO:root:De la sesion 317 se actualizaron 0 registros
INFO:root:De la sesion 318 se actualizaron 0 registros
INFO:root:De la sesion 321 se actualizaron 0 registros
INFO:root:No se han eliminado sesiones
INFO:root:No se han eliminado sesiones
INFO:root:No se han eliminado sesiones
INFO:root:No se han eliminado sesiones
INFO:root:No se han eliminado sesiones
INFO:root:No se han eliminado sesiones
INFO:root:No se han eliminado sesiones
INFO:root:No se han eliminado sesiones
INFO:root:No se han eliminado sesiones
INFO:root:No se han eliminado sesiones
INFO:root:No se han eliminado sesiones
INFO:root:No se han eliminado sesiones
INFO:root:No se han eliminado sesiones
INFO:root:No se han eliminado sesiones
INFO:root:No se han eliminado sesiones
INFO:django.utils.autoreload:/home/martin/PycharmProjects/Torque/models/views.py changed, reloading.
INFO:root:SEPARE_SESSIONS STARTED 
INFO:root:SEPARE_SESSIONS STARTED 
INFO:root:SEPARE_SESSIONS STARTED 
ERROR:django.request:Internal Server Error: /separe_sessions
Traceback (most recent call last):
  File "/home/martin/PycharmProjects/Torque/venv/lib/python3.8/site-packages/django/core/handlers/exception.py", line 47, in inner
    response = get_response(request)
  File "/home/martin/PycharmProjects/Torque/venv/lib/python3.8/site-packages/django/core/handlers/base.py", line 181, in _get_response
    response = wrapped_callback(request, *callback_args, **callback_kwargs)
  File "/usr/lib/python3.8/contextlib.py", line 75, in inner
    return func(*args, **kwds)
  File "/home/martin/PycharmProjects/Torque/models/views.py", line 776, in separe_sessions
    return render(request, 'success.html', context=context)
  File "/home/martin/PycharmProjects/Torque/venv/lib/python3.8/site-packages/django/shortcuts.py", line 19, in render
    content = loader.render_to_string(template_name, context, request, using=using)
  File "/home/martin/PycharmProjects/Torque/venv/lib/python3.8/site-packages/django/template/loader.py", line 62, in render_to_string
    return template.render(context, request)
  File "/home/martin/PycharmProjects/Torque/venv/lib/python3.8/site-packages/django/template/backends/django.py", line 61, in render
    return self.template.render(context)
  File "/home/martin/PycharmProjects/Torque/venv/lib/python3.8/site-packages/django/template/base.py", line 170, in render
    return self._render(context)
  File "/home/martin/PycharmProjects/Torque/venv/lib/python3.8/site-packages/django/template/base.py", line 162, in _render
    return self.nodelist.render(context)
  File "/home/martin/PycharmProjects/Torque/venv/lib/python3.8/site-packages/django/template/base.py", line 938, in render
    bit = node.render_annotated(context)
  File "/home/martin/PycharmProjects/Torque/venv/lib/python3.8/site-packages/django/template/base.py", line 905, in render_annotated
    return self.render(context)
  File "/home/martin/PycharmProjects/Torque/venv/lib/python3.8/site-packages/django/template/loader_tags.py", line 127, in render
    compiled_parent = self.get_parent(context)
  File "/home/martin/PycharmProjects/Torque/venv/lib/python3.8/site-packages/django/template/loader_tags.py", line 124, in get_parent
    return self.find_template(parent, context)
  File "/home/martin/PycharmProjects/Torque/venv/lib/python3.8/site-packages/django/template/loader_tags.py", line 103, in find_template
    template, origin = context.template.engine.find_template(
  File "/home/martin/PycharmProjects/Torque/venv/lib/python3.8/site-packages/django/template/engine.py", line 125, in find_template
    template = loader.get_template(name, skip=skip)
  File "/home/martin/PycharmProjects/Torque/venv/lib/python3.8/site-packages/django/template/loaders/base.py", line 29, in get_template
    return Template(
  File "/home/martin/PycharmProjects/Torque/venv/lib/python3.8/site-packages/django/template/base.py", line 155, in __init__
    self.nodelist = self.compile_nodelist()
  File "/home/martin/PycharmProjects/Torque/venv/lib/python3.8/site-packages/django/template/base.py", line 193, in compile_nodelist
    return parser.parse()
  File "/home/martin/PycharmProjects/Torque/venv/lib/python3.8/site-packages/django/template/base.py", line 478, in parse
    raise self.error(token, e)
  File "/home/martin/PycharmProjects/Torque/venv/lib/python3.8/site-packages/django/template/base.py", line 476, in parse
    compiled_result = compile_func(self, token)
  File "/home/martin/PycharmProjects/Torque/venv/lib/python3.8/site-packages/django/template/loader_tags.py", line 213, in do_block
    nodelist = parser.parse(('endblock',))
  File "/home/martin/PycharmProjects/Torque/venv/lib/python3.8/site-packages/django/template/base.py", line 478, in parse
    raise self.error(token, e)
  File "/home/martin/PycharmProjects/Torque/venv/lib/python3.8/site-packages/django/template/base.py", line 476, in parse
    compiled_result = compile_func(self, token)
  File "/home/martin/PycharmProjects/Torque/venv/lib/python3.8/site-packages/django/template/loader_tags.py", line 209, in do_block
    raise TemplateSyntaxError("'%s' tag with name '%s' appears more than once" % (bits[0], block_name))
django.template.exceptions.TemplateSyntaxError: 'block' tag with name 'body' appears more than once
INFO:root:SEPARE_SESSIONS STARTED 
INFO:root:SEPARE_SESSIONS STARTED 
INFO:root:SEPARE_SESSIONS STARTED 
INFO:root:SEPARE_SESSIONS STARTED 
INFO:root:SEPARE_SESSIONS STARTED 
INFO:root:SEPARE_SESSIONS STARTED 
INFO:root:SEPARE_SESSIONS STARTED 
INFO:root:SEPARE_SESSIONS STARTED 
INFO:root:SEPARE_SESSIONS STARTED 
INFO:root:TRACKING_ALL_SESSIONS STARTED
INFO:root:Se vacia la tabla TrackLog para volver a obtener los nombres de las calles de todas las sesiones
INFO:django.utils.autoreload:/home/martin/PycharmProjects/Torque/models/views.py changed, reloading.
INFO:root:TRACKING_ALL_SESSIONS STARTED
INFO:root:Se vacia la tabla TrackLog para volver a obtener los nombres de las calles de todas las sesiones
INFO:root:TRACKING_ALL_SESSIONS STARTED
INFO:root:Se vacia la tabla TrackLog para volver a obtener los nombres de las calles de todas las sesiones
INFO:django.utils.autoreload:/home/martin/PycharmProjects/Torque/models/views.py changed, reloading.
INFO:django.utils.autoreload:/home/martin/PycharmProjects/Torque/models/views.py changed, reloading.
INFO:django.utils.autoreload:/home/martin/PycharmProjects/Torque/models/views.py changed, reloading.
INFO:django.utils.autoreload:/home/martin/PycharmProjects/Torque/models/views.py changed, reloading.
INFO:django.utils.autoreload:/home/martin/PycharmProjects/Torque/models/views.py changed, reloading.
INFO:django.utils.autoreload:/home/martin/PycharmProjects/Torque/models/views.py changed, reloading.
INFO:django.utils.autoreload:/home/martin/PycharmProjects/Torque/models/views.py changed, reloading.
INFO:django.utils.autoreload:/home/martin/PycharmProjects/Torque/models/views.py changed, reloading.
INFO:django.utils.autoreload:/home/martin/PycharmProjects/Torque/models/views.py changed, reloading.
INFO:django.utils.autoreload:/home/martin/PycharmProjects/Torque/models/views.py changed, reloading.
INFO:django.utils.autoreload:/home/martin/PycharmProjects/Torque/models/views.py changed, reloading.
